Workbook

Sheet Inputs
A1: Tail-Expert Value Model — Inputs
A2: Edit the blue/yellow cells only. Every other sheet recalculates from these.
A4: DISTRIBUTION
A5: Distribution (1=Pareto, 2=Lognormal, 3=Weibull, 4=Normal) | B5: 1 | C5: All four are fitted to the same anchors below; the Compare sheet shows all four side by side.
A6: Fitted shape applies to (1 = value added V, 2 = skill S, so V is proportional to S^2) | B6: 1 | C6: Option 2 squares the fitted variable. For a Pareto this halves the effective exponent.
A8: FITTING ANCHORS — two upper-tail quantiles
A9: Anchor 1 — upper-tail probability (0.5 = median) | B9: 0.5
A10: Anchor 1 — skill value (bp per month) | B10: 43 | C10: PST (2015) report 42 bp/month as the MEAN, not the median. See the Notes sheet.
A11: Anchor 2 — upper-tail probability (0.1 = 90th percentile) | B11: 0.1
A12: Anchor 2 — skill value (bp per month) | B12: 123 | C12: PST (2015): 90th percentile of fund skill, 123 bp/month in 2011.
A13: Target mean for Goal Seek (bp per month) | B13: 42 | C13: Not used in the calculation. The Diagnostics block on Results shows the gap; run Goal Seek on it to solve an anchor.
A15: POPULATION
A16: Number of decision-makers (N) | B16: 2264400
A17: Rank-1 plotting constant (0.5 = Hazen, 1.0 = Weibull) | B17: 0.5 | C17: Affects the single best person only; ranks past about 50 are insensitive to it.
A18: Bands per tier segment (fixed when the Grid was built) | B18: 60 | C18: Read-only — changing this requires rebuilding the Grid sheet.
A20: TIER BOUNDARIES — upper-tail fraction of the population
A21: Tier 1 upper edge (top 0.01%) | B21: 0.0001
A22: Tier 2 upper edge (top 0.1%) | B22: 0.001
A23: Tier 3 upper edge (top 1%) | B23: 0.01
A24: Tier 4 upper edge (top 10%) | B24: 0.1
A25: Tier 5 upper edge (all) | B25: 1
A27: ALPHA POOL SCENARIOS ($ per year)
A28: Pool 1 — primary; drives A* and S | B28: 1200000000000
A29: Pool 2 | B29: 840000000000
A30: Pool 3 | B30: 600000000000
A31: Pool 4 | B31: 400000000000
C32: Total gross alpha available to the whole population each year.
A34: CAPITAL AND COMPARATORS
A35: Capital run by the top 1% ($) | B35: 30000000000000 | C35: An assumption, not a measurement. See the Diagnostics block on the Results sheet for the gross alpha it implies.
A36: Reference gross alpha for comparison | B36: 0.008 | C36: Berk & van Binsbergen (2015) Table 8: 6.5 bp/month value-weighted, about 0.80%/yr.
A37: Average financial services salary ($) | B37: 52804 | C37: User-supplied.

Sheet Results
A1: Value added and optimal book size by tier
A2: ="Distribution: "&Fit!B33&" | shape applied to "&IF(Inputs!B6=1,"value added V","skill S (V proportional to S^2)")&" | N = "&TEXT(Inputs!B16,"#,##0") -> Distribution: Pareto | shape applied to value added V | N = 2,264,400
A4: Tier | B4: People | C4: Share of pool | D4: V* at Pool 1 | E4: V* at Pool 2 | F4: V* at Pool 3 | G4: V* at Pool 4 | H4: A* (Pool 1) | I4: S (Pool 1) | J4: x avg salary
A5: Single best (rank 1) | B5: =Grid!F3 -> 1 | C5: =Grid!O3/Grid!$AB$1 -> 0.0034124819 | D5: =$C5*Inputs!$B$28/$B5 -> 4.0949783e+09 | E5: =$C5*Inputs!$B$29/$B5 -> 2.8664848e+09 | F5: =$C5*Inputs!$B$30/$B5 -> 2.0474891e+09 | G5: =$C5*Inputs!$B$31/$B5 -> 1.3649928e+09 | H5: =Grid!R3 -> 2.9566732e+10 | I5: =Grid!S3 -> 0.27699904 | J5: =D5/Inputs!$B$37 -> 77550.531
A6: Top 0.01% | B6: =SUMIF(Grid!$G$3:$G$303,1,Grid!$F$3:$F$303) -> 226.44 | C6: =SUMIF(Grid!$G$3:$G$303,1,Grid!$O$3:$O$303)/Grid!$AB$1 -> 0.038195879 | D6: =$C6*Inputs!$B$28/$B6 -> 2.0241589e+08 | E6: =$C6*Inputs!$B$29/$B6 -> 1.4169113e+08 | F6: =$C6*Inputs!$B$30/$B6 -> 1.0120795e+08 | G6: =$C6*Inputs!$B$31/$B6 -> 67471964 | H6: =SUMIF(Grid!$G$3:$G$303,1,Grid!$T$3:$T$303)/B6 -> 5.93549e+09 | I6: =2*Grid!$AB$6*H6 -> 0.055607262 | J6: =D6/Inputs!$B$37 -> 3833.3439
A7: Rest of top 0.1% | B7: =SUMIF(Grid!$G$3:$G$303,2,Grid!$F$3:$F$303) -> 2037.96 | C7: =SUMIF(Grid!$G$3:$G$303,2,Grid!$O$3:$O$303)/Grid!$AB$1 -> 0.050211379 | D7: =$C7*Inputs!$B$28/$B7 -> 29565671 | E7: =$C7*Inputs!$B$29/$B7 -> 20695970 | F7: =$C7*Inputs!$B$30/$B7 -> 14782836 | G7: =$C7*Inputs!$B$31/$B7 -> 9855223.7 | H7: =SUMIF(Grid!$G$3:$G$303,2,Grid!$T$3:$T$303)/B7 -> 2.460331e+09 | I7: =2*Grid!$AB$6*H7 -> 0.02304987 | J7: =D7/Inputs!$B$37 -> 559.91347
A8: Rest of top 1% | B8: =SUMIF(Grid!$G$3:$G$303,3,Grid!$F$3:$F$303) -> 20379.6 | C8: =SUMIF(Grid!$G$3:$G$303,3,Grid!$O$3:$O$303)/Grid!$AB$1 -> 0.11163206 | D8: =$C8*Inputs!$B$28/$B8 -> 6573164.8 | E8: =$C8*Inputs!$B$29/$B8 -> 4601215.3 | F8: =$C8*Inputs!$B$30/$B8 -> 3286582.4 | G8: =$C8*Inputs!$B$31/$B8 -> 2191054.9 | H8: =SUMIF(Grid!$G$3:$G$303,3,Grid!$T$3:$T$303)/B8 -> 1.1600773e+09 | I8: =2*Grid!$AB$6*H8 -> 0.010868306 | J8: =D8/Inputs!$B$37 -> 124.48233
A9: Top 1% (cumulative) | B9: =SUMIF(Grid!$G$3:$G$303,"<=3",Grid!$F$3:$F$303) -> 22644 | C9: =SUMIF(Grid!$G$3:$G$303,"<=3",Grid!$O$3:$O$303)/Grid!$AB$1 -> 0.20003932 | D9: =$C9*Inputs!$B$28/$B9 -> 10600918 | E9: =$C9*Inputs!$B$29/$B9 -> 7420642.3 | F9: =$C9*Inputs!$B$30/$B9 -> 5300458.8 | G9: =$C9*Inputs!$B$31/$B9 -> 3533639.2 | H9: =Grid!$AB$8/B9 -> 1.3248543e+09 | I9: =2*Grid!$AB$6*H9 -> 0.012412036 | J9: =D9/Inputs!$B$37 -> 200.75975
A10: Rest of top 10% | B10: =SUMIF(Grid!$G$3:$G$303,4,Grid!$F$3:$F$303) -> 203796 | C10: =SUMIF(Grid!$G$3:$G$303,4,Grid!$O$3:$O$303)/Grid!$AB$1 -> 0.2481851 | D10: =$C10*Inputs!$B$28/$B10 -> 1461373.7 | E10: =$C10*Inputs!$B$29/$B10 -> 1022961.6 | F10: =$C10*Inputs!$B$30/$B10 -> 730686.86 | G10: =$C10*Inputs!$B$31/$B10 -> 487124.57 | H10: — | I10: — | J10: =D10/Inputs!$B$37 -> 27.675436
A11: Bottom 90% | B11: =SUMIF(Grid!$G$3:$G$303,5,Grid!$F$3:$F$303) -> 2037960 | C11: =SUMIF(Grid!$G$3:$G$303,5,Grid!$O$3:$O$303)/Grid!$AB$1 -> 0.55177559 | D11: =$C11*Inputs!$B$28/$B11 -> 324898.77 | E11: =$C11*Inputs!$B$29/$B11 -> 227429.14 | F11: =$C11*Inputs!$B$30/$B11 -> 162449.39 | G11: =$C11*Inputs!$B$31/$B11 -> 108299.59 | H11: — | I11: — | J11: =D11/Inputs!$B$37 -> 6.1529197
A12: Total | B12: =SUM(Grid!$F$3:$F$303) -> 2264400 | C12: =SUM(Grid!$O$3:$O$303)/Grid!$AB$1 -> 1 | D12: =$C12*Inputs!$B$28/$B12 -> 529941.71 | E12: =$C12*Inputs!$B$29/$B12 -> 370959.19 | F12: =$C12*Inputs!$B$30/$B12 -> 264970.85 | G12: =$C12*Inputs!$B$31/$B12 -> 176647.24 | J12: =D12/Inputs!$B$37 -> 10.036014
A13: V* and A* are per person, per year. S is raw alpha on the first dollar; the alpha earned at the optimum is S/2.
A14: A* and S are shown for Pool 1 only, and are computed on the top 1% (the book-running population). A* scales linearly with the pool.
A16: DIAGNOSTICS
A17: Active distribution | B17: =Fit!B33 -> Pareto
A18: b — decay parameter (per $ of AUM) | B18: =Grid!$AB$6 -> 4.6843026e-12
A19: Total A* of the top 1% ($) | B19: =Grid!$AB$8 -> 30000000000000
A20: Capital input, top 1% ($) | B20: =Inputs!$B$35 -> 30000000000000
A21: Difference (should be zero) | B21: =B19-B20 -> 0
A22: Top 1% total value added ($/yr) | B22: =C9*Inputs!$B$28 -> 2.4004718e+11
A23: Implied gross alpha on top-1% books | B23: =B22/Inputs!$B$35 -> 0.0080015726
A24: Reference gross alpha (Berk & van Binsbergen 2015) | B24: =Inputs!$B$36 -> 0.008
A25: Difference (implied minus reference) | B25: =B23-B24 -> 1.5726137e-06
A26: Implied mean skill, finite population (bp/mo) | B26: =Grid!$AB$2 -> 78.580248
A27: Theoretical mean of the fitted distribution (bp/mo) | B27: =Fit!$B$34 -> 78.809571
A28: Target mean (bp/mo) | B28: =Inputs!$B$13 -> 42
A29: Gap vs target — Goal Seek this cell to zero | B29: =B26-B28 -> 36.580248
A30: Pareto feasibility flag | B30: =Fit!$B$48 -> NO - no Pareto matches this mean with this 90th percentile
A32: The implied gross alpha above is an OUTPUT. It equals the reference only if the capital input happens to make it so; it is not a test that can pass on its own.

Sheet Compare
A1: All four distributions, same anchors — share of the alpha pool by tier
A2: Independent of the pool size and of the capital assumption. Shape only.
A4: Tier | B4: Pareto | C4: Lognormal | D4: Weibull | E4: Normal
A5: Single best (rank 1) | B5: =Grid!V3/SUM(Grid!$V$3:$V$303) -> 0.0034124819 | C5: =Grid!W3/SUM(Grid!$W$3:$W$303) -> 1.9840526e-05 | D5: =Grid!X3/SUM(Grid!$X$3:$X$303) -> 5.0517681e-06 | E5: =Grid!Y3/SUM(Grid!$Y$3:$Y$303) -> 3.0378068e-06
A6: Top 0.01% | B6: =SUMIF(Grid!$G$3:$G$303,1,Grid!$V$3:$V$303)/SUM(Grid!$V$3:$V$303) -> 0.038195879 | C6: =SUMIF(Grid!$G$3:$G$303,1,Grid!$W$3:$W$303)/SUM(Grid!$W$3:$W$303) -> 0.0018705018 | D6: =SUMIF(Grid!$G$3:$G$303,1,Grid!$X$3:$X$303)/SUM(Grid!$X$3:$X$303) -> 0.00080114188 | E6: =SUMIF(Grid!$G$3:$G$303,1,Grid!$Y$3:$Y$303)/SUM(Grid!$Y$3:$Y$303) -> 0.00055700024
A7: Rest of top 0.1% | B7: =SUMIF(Grid!$G$3:$G$303,2,Grid!$V$3:$V$303)/SUM(Grid!$V$3:$V$303) -> 0.050211379 | C7: =SUMIF(Grid!$G$3:$G$303,2,Grid!$W$3:$W$303)/SUM(Grid!$W$3:$W$303) -> 0.0097250826 | D7: =SUMIF(Grid!$G$3:$G$303,2,Grid!$X$3:$X$303)/SUM(Grid!$X$3:$X$303) -> 0.0056030045 | E7: =SUMIF(Grid!$G$3:$G$303,2,Grid!$Y$3:$Y$303)/SUM(Grid!$Y$3:$Y$303) -> 0.0043044763
A8: Rest of top 1% | B8: =SUMIF(Grid!$G$3:$G$303,3,Grid!$V$3:$V$303)/SUM(Grid!$V$3:$V$303) -> 0.11163206 | C8: =SUMIF(Grid!$G$3:$G$303,3,Grid!$W$3:$W$303)/SUM(Grid!$W$3:$W$303) -> 0.054388718 | D8: =SUMIF(Grid!$G$3:$G$303,3,Grid!$X$3:$X$303)/SUM(Grid!$X$3:$X$303) -> 0.04094262 | E8: =SUMIF(Grid!$G$3:$G$303,3,Grid!$Y$3:$Y$303)/SUM(Grid!$Y$3:$Y$303) -> 0.035340726
A9: Top 1% (cumulative) | B9: =SUMIF(Grid!$G$3:$G$303,"<=3",Grid!$V$3:$V$303)/SUM(Grid!$V$3:$V$303) -> 0.20003932 | C9: =SUMIF(Grid!$G$3:$G$303,"<=3",Grid!$W$3:$W$303)/SUM(Grid!$W$3:$W$303) -> 0.065984302 | D9: =SUMIF(Grid!$G$3:$G$303,"<=3",Grid!$X$3:$X$303)/SUM(Grid!$X$3:$X$303) -> 0.047346766 | E9: =SUMIF(Grid!$G$3:$G$303,"<=3",Grid!$Y$3:$Y$303)/SUM(Grid!$Y$3:$Y$303) -> 0.040202203
A10: Rest of top 10% | B10: =SUMIF(Grid!$G$3:$G$303,4,Grid!$V$3:$V$303)/SUM(Grid!$V$3:$V$303) -> 0.2481851 | C10: =SUMIF(Grid!$G$3:$G$303,4,Grid!$W$3:$W$303)/SUM(Grid!$W$3:$W$303) -> 0.25617378 | D10: =SUMIF(Grid!$G$3:$G$303,4,Grid!$X$3:$X$303)/SUM(Grid!$X$3:$X$303) -> 0.24980142 | E10: =SUMIF(Grid!$G$3:$G$303,4,Grid!$Y$3:$Y$303)/SUM(Grid!$Y$3:$Y$303) -> 0.25271705
A11: Bottom 90% | B11: =SUMIF(Grid!$G$3:$G$303,5,Grid!$V$3:$V$303)/SUM(Grid!$V$3:$V$303) -> 0.55177559 | C11: =SUMIF(Grid!$G$3:$G$303,5,Grid!$W$3:$W$303)/SUM(Grid!$W$3:$W$303) -> 0.67784192 | D11: =SUMIF(Grid!$G$3:$G$303,5,Grid!$X$3:$X$303)/SUM(Grid!$X$3:$X$303) -> 0.70285181 | E11: =SUMIF(Grid!$G$3:$G$303,5,Grid!$Y$3:$Y$303)/SUM(Grid!$Y$3:$Y$303) -> 0.70708074
A13: FITTED PARAMETERS AND IMPLIED MOMENTS
A14: parameter 1 | B14: ="alpha = "&TEXT(Fit!B9,"0.000") -> alpha = 1.531 | C14: ="sigma = "&TEXT(Fit!B15,"0.000") -> sigma = 0.820 | D14: ="kappa = "&TEXT(Fit!B21,"0.000") -> kappa = 1.142 | E14: ="sd = "&TEXT(Fit!B27,"0.00") -> sd = 62.42
A15: parameter 2 | B15: ="x_min = "&TEXT(Fit!B10,"0.00") -> x_min = 27.35 | C15: ="mu = "&TEXT(Fit!B16,"0.000") -> mu = 3.761 | D15: ="lambda = "&TEXT(Fit!B22,"0.00") -> lambda = 59.27 | E15: ="mean = "&TEXT(Fit!B28,"0.00") -> mean = 43.00
A16: theoretical mean (bp/mo) | B16: =Fit!B11 -> 78.809571 | C16: =Fit!B17 -> 60.187925 | D16: =Fit!B23 -> 56.516024 | E16: =Fit!B29 -> 43
A17: theoretical median (bp/mo) | B17: =Fit!B12 -> 43 | C17: =Fit!B18 -> 43 | D17: =Fit!B24 -> 43 | E17: =Fit!B30 -> 43
A19: Compare each theoretical mean against the target mean on the Inputs sheet. A large gap means that distribution cannot reproduce the source's reported mean.

Sheet Fit
A1: Distribution fitting — two upper-tail quantiles, closed form
A2: p = upper-tail probability, so p=0.5 is the median and p=0.1 the 90th percentile. Every parameter is derived.
A4: Standard normal deviates
A5: z1 = -NORMSINV(p1) | B5: =-NORMSINV(Inputs!B9) -> 0
A6: z2 = -NORMSINV(p2) | B6: =-NORMSINV(Inputs!B11) -> 1.2815516
A8: PARETO
A9: alpha | B9: =LN(Inputs!B9/Inputs!B11)/LN(Inputs!B12/Inputs!B10) -> 1.5313626
A10: x_min (bp/mo) | B10: =Inputs!B10*Inputs!B9^(1/B9) -> 27.345879
A11: theoretical mean | B11: =IF(B9>1,B9*B10/(B9-1),-1) -> 78.809571 | C11: -1 means the mean is divergent (alpha <= 1).
A12: theoretical median | B12: =B10*2^(1/B9) -> 43
A14: LOGNORMAL
A15: sigma | B15: =(LN(Inputs!B12)-LN(Inputs!B10))/(B6-B5) -> 0.82008736
A16: mu | B16: =LN(Inputs!B10)-B15*B5 -> 3.7612001
A17: theoretical mean | B17: =EXP(B16+B15^2/2) -> 60.187925
A18: theoretical median | B18: =EXP(B16) -> 43
A20: WEIBULL
A21: kappa (shape) | B21: =LN(LN(1/Inputs!B11)/LN(1/Inputs!B9))/LN(Inputs!B12/Inputs!B10) -> 1.1423058
A22: lambda (scale) | B22: =Inputs!B10/LN(1/Inputs!B9)^(1/B21) -> 59.267063
A23: theoretical mean | B23: =B22*EXP(GAMMALN(1+1/B21)) -> 56.516024
A24: theoretical median | B24: =B22*LN(2)^(1/B21) -> 43
A26: NORMAL
A27: s (standard deviation) | B27: =(Inputs!B12-Inputs!B10)/(B6-B5) -> 62.424332
A28: m (mean) | B28: =Inputs!B10-B27*B5 -> 43 | C28: Quantiles are floored at zero: a normal fitted to these anchors goes negative in the lower tail.
A29: theoretical mean | B29: =B28 -> 43
A30: theoretical median | B30: =B28 -> 43
A32: ACTIVE DISTRIBUTION
A33: name | B33: =CHOOSE(Inputs!B5,"Pareto","Lognormal","Weibull","Normal") -> Pareto
A34: theoretical mean (bp/mo) | B34: =CHOOSE(Inputs!B5,B11,B17,B23,B29) -> 78.809571
A35: theoretical median (bp/mo) | B35: =CHOOSE(Inputs!B5,B12,B18,B24,B30) -> 43
A37: QUANTILE SPOT-CHECKS (active distribution)
B38: u (upper-tail p) | C38: bp/month | D38: % per year
A39: anchor 1 — should equal the input | B39: =Inputs!B9 -> 0.5 | C39: =CHOOSE(Inputs!$B$5,$B$10*B39^(-1/$B$9),EXP($B$16+$B$15*-NORMSINV(B39)),$B$22*LN(1/B39)^(1/$B$21),MAX(0,$B$28+$B$27*-NORMSINV(B39))) -> 43 | D39: =C39*12/100 -> 5.16
A40: anchor 2 — should equal the input | B40: =Inputs!B11 -> 0.1 | C40: =CHOOSE(Inputs!$B$5,$B$10*B40^(-1/$B$9),EXP($B$16+$B$15*-NORMSINV(B40)),$B$22*LN(1/B40)^(1/$B$21),MAX(0,$B$28+$B$27*-NORMSINV(B40))) -> 123 | D40: =C40*12/100 -> 14.76
A41: 99th percentile | B41: 0.01 | C41: =CHOOSE(Inputs!$B$5,$B$10*B41^(-1/$B$9),EXP($B$16+$B$15*-NORMSINV(B41)),$B$22*LN(1/B41)^(1/$B$21),MAX(0,$B$28+$B$27*-NORMSINV(B41))) -> 553.24607 | D41: =C41*12/100 -> 66.389528
A42: 99.9th percentile | B42: 0.001 | C42: =CHOOSE(Inputs!$B$5,$B$10*B42^(-1/$B$9),EXP($B$16+$B$15*-NORMSINV(B42)),$B$22*LN(1/B42)^(1/$B$21),MAX(0,$B$28+$B$27*-NORMSINV(B42))) -> 2488.4651 | D42: =C42*12/100 -> 298.61582
A43: 99.99th percentile | B43: 0.0001 | C43: =CHOOSE(Inputs!$B$5,$B$10*B43^(-1/$B$9),EXP($B$16+$B$15*-NORMSINV(B43)),$B$22*LN(1/B43)^(1/$B$21),MAX(0,$B$28+$B$27*-NORMSINV(B43))) -> 11192.956 | D43: =C43*12/100 -> 1343.1547
A45: PARETO FEASIBILITY CHECK
A46: required mean / anchor-2 value | B46: =Inputs!B13/Inputs!B12 -> 0.34146341
A47: minimum ratio any Pareto can attain | B47: 0.6259
A48: feasible? | B48: =IF(B46>=B47,"yes","NO - no Pareto matches this mean with this 90th percentile") -> NO - no Pareto matches this mean with this 90th percentile
...

Sheet Grid
A1: Numerical grid — 301 population bands (row 3 is rank 1; 60 log-spaced bands per tier) | AA1: T = SUM(w*du) | AB1: =SUM(O3:O303) -> 78.580248
A2: j | B2: u_lo | C2: u_hi | D2: u_mid | E2: du | F2: people | G2: tier | H2: x Pareto | I2: x Lognorm | J2: x Weibull | K2: x Normal | L2: x active | M2: x*du | N2: w = x^pwr | O2: w*du | P2: V per person | Q2: ppl*SQRT(V) | R2: A* | S2: S | T2: ppl*A* | U2: ppl*V | V2: contrib Par | W2: contrib Logn | X2: contrib Weib | Y2: contrib Norm | AA2: Mean of x, finite population | AB2: =SUM(M3:M303) -> 78.580248
A3: 1 | B3: 0 | C3: =1/Inputs!$B$16 -> 4.4161809e-07 | D3: =Inputs!$B$17/Inputs!$B$16 -> 2.2080904e-07 | E3: =C3-B3 -> 4.4161809e-07 | F3: =Inputs!$B$16*E3 -> 1 | G3: =IF(D3<=Inputs!$B$21,1,IF(D3<=Inputs!$B$22,2,IF(D3<=Inputs!$B$23,3,IF(D3<=Inputs!$B$24,4,5)))) -> 1 | H3: =Fit!$B$10*D3^(-1/Fit!$B$9) -> 607207.18 | I3: =EXP(Fit!$B$16+Fit!$B$15*-NORMSINV(D3)) -> 2704.6002 | J3: =Fit!$B$22*LN(1/D3)^(1/Fit!$B$21) -> 646.49248 | K3: =MAX(0,Fit!$B$28+Fit!$B$27*-NORMSINV(D3)) -> 358.24806 | L3: =INDEX(H3:K3,1,Inputs!$B$5) -> 607207.18 | M3: =L3*E3 -> 0.26815367 | N3: =L3^$AB$7 -> 607207.18 | O3: =N3*E3 -> 0.26815367 | P3: =N3*$AB$3/($AB$4*$AB$1) -> 4.0949783e+09 | Q3: =IF(G3<=3,F3*SQRT(P3),0) -> 63992.017 | R3: =SQRT(P3/$AB$6) -> 2.9566732e+10 | S3: =2*$AB$6*R3 -> 0.27699904 | T3: =IF(G3<=3,F3*R3,0) -> 2.9566732e+10 | U3: =F3*P3 -> 4.0949783e+09 | V3: =H3^$AB$7*E3 -> 0.26815367 | W3: =I3^$AB$7*E3 -> 0.0011944004 | X3: =J3^$AB$7*E3 -> 0.00028550277 | Y3: =K3^$AB$7*E3 -> 0.00015820882 | AA3: Pool 1 ($) | AB3: =Inputs!$B$28 -> 1200000000000
A4: 2 | B4: =C3 -> 4.4161809e-07 | C4: =(1/Inputs!$B$16)*(Inputs!$B$21/(1/Inputs!$B$16))^(1/60) -> 4.8338823e-07 | D4: =(B4+C4)/2 -> 4.6250316e-07 | E4: =C4-B4 -> 4.1770143e-08 | F4: =Inputs!$B$16*E4 -> 0.094584311 | G4: =IF(D4<=Inputs!$B$21,1,IF(D4<=Inputs!$B$22,2,IF(D4<=Inputs!$B$23,3,IF(D4<=Inputs!$B$24,4,5)))) -> 1 | H4: =Fit!$B$10*D4^(-1/Fit!$B$9) -> 374675.9 | I4: =EXP(Fit!$B$16+Fit!$B$15*-NORMSINV(D4)) -> 2405.0668 | J4: =Fit!$B$22*LN(1/D4)^(1/Fit!$B$21) -> 619.10617 | K4: =MAX(0,Fit!$B$28+Fit!$B$27*-NORMSINV(D4)) -> 349.31347 | L4: =INDEX(H4:K4,1,Inputs!$B$5) -> 374675.9 | M4: =L4*E4 -> 0.015650266 | N4: =L4^$AB$7 -> 374675.9 | O4: =N4*E4 -> 0.015650266 | P4: =N4*$AB$3/($AB$4*$AB$1) -> 2.5267976e+09 | Q4: =IF(G4<=3,F4*SQRT(P4),0) -> 4754.4944 | R4: =SQRT(P4/$AB$6) -> 2.3225376e+10 | S4: =2*$AB$6*R4 -> 0.21758938 | T4: =IF(G4<=3,F4*R4,0) -> 2.1967562e+09 | U4: =F4*P4 -> 2.3899541e+08 | V4: =H4^$AB$7*E4 -> 0.015650266 | W4: =I4^$AB$7*E4 -> 0.00010045998 | X4: =J4^$AB$7*E4 -> 2.5860153e-05 | Y4: =K4^$AB$7*E4 -> 1.4590873e-05 | AA4: N | AB4: =Inputs!$B$16 -> 2264400
A5: 3 | B5: =C4 -> 4.8338823e-07 | C5: =(1/Inputs!$B$16)*(Inputs!$B$21/(1/Inputs!$B$16))^(2/60) -> 5.2910917e-07 | D5: =(B5+C5)/2 -> 5.062487e-07 | E5: =C5-B5 -> 4.5720943e-08 | F5: =Inputs!$B$16*E5 -> 0.1035305 | G5: =IF(D5<=Inputs!$B$21,1,IF(D5<=Inputs!$B$22,2,IF(D5<=Inputs!$B$23,3,IF(D5<=Inputs!$B$24,4,5)))) -> 1 | H5: =Fit!$B$10*D5^(-1/Fit!$B$9) -> 353203.91 | I5: =EXP(Fit!$B$16+Fit!$B$15*-NORMSINV(D5)) -> 2370.2867 | J5: =Fit!$B$22*LN(1/D5)^(1/Fit!$B$21) -> 615.74692 | K5: =MAX(0,Fit!$B$28+Fit!$B$27*-NORMSINV(D5)) -> 348.20466 | L5: =INDEX(H5:K5,1,Inputs!$B$5) -> 353203.91 | M5: =L5*E5 -> 0.016148816 | N5: =L5^$AB$7 -> 353203.91 | O5: =N5*E5 -> 0.016148816 | P5: =N5*$AB$3/($AB$4*$AB$1) -> 2.3819915e+09 | Q5: =IF(G5<=3,F5*SQRT(P5),0) -> 5052.8735 | R5: =SQRT(P5/$AB$6) -> 2.2550056e+10 | S5: =2*$AB$6*R5 -> 0.21126257 | T5: =IF(G5<=3,F5*R5,0) -> 2.3346187e+09 | U5: =F5*P5 -> 2.4660878e+08 | V5: =H5^$AB$7*E5 -> 0.016148816 | W5: =I5^$AB$7*E5 -> 0.00010837174 | X5: =J5^$AB$7*E5 -> 2.815253e-05 | Y5: =K5^$AB$7*E5 -> 1.5920245e-05 | AA5: SUM people*SQRT(V), top 1% | AB5: =SUM(Q3:Q303) -> 64929749
A6: 4 | B6: =C5 -> 5.2910917e-07 | C6: =(1/Inputs!$B$16)*(Inputs!$B$21/(1/Inputs!$B$16))^(3/60) -> 5.791546e-07 | D6: =(B6+C6)/2 -> 5.5413189e-07 | E6: =C6-B6 -> 5.0045427e-08 | F6: =Inputs!$B$16*E6 -> 0.11332286 | G6: =IF(D6<=Inputs!$B$21,1,IF(D6<=Inputs!$B$22,2,IF(D6<=Inputs!$B$23,3,IF(D6<=Inputs!$B$24,4,5)))) -> 1 | H6: =Fit!$B$10*D6^(-1/Fit!$B$9) -> 332962.43 | I6: =EXP(Fit!$B$16+Fit!$B$15*-NORMSINV(D6)) -> 2335.8943 | J6: =Fit!$B$22*LN(1/D6)^(1/Fit!$B$21) -> 612.38505 | K6: =MAX(0,Fit!$B$28+Fit!$B$27*-NORMSINV(D6)) -> 347.09209 | L6: =INDEX(H6:K6,1,Inputs!$B$5) -> 332962.43 | M6: =L6*E6 -> 0.016663247 | N6: =L6^$AB$7 -> 332962.43 | O6: =N6*E6 -> 0.016663247 | P6: =N6*$AB$3/($AB$4*$AB$1) -> 2.2454839e+09 | Q6: =IF(G6<=3,F6*SQRT(P6),0) -> 5369.9781 | R6: =SQRT(P6/$AB$6) -> 2.1894372e+10 | S6: =2*$AB$6*R6 -> 0.20511973 | T6: =IF(G6<=3,F6*R6,0) -> 2.481133e+09 | U6: =F6*P6 -> 2.5446467e+08 | V6: =H6^$AB$7*E6 -> 0.016663247 | W6: =I6^$AB$7*E6 -> 0.00011690083 | X6: =J6^$AB$7*E6 -> 3.0647071e-05 | Y6: =K6^$AB$7*E6 -> 1.7370372e-05 | AA6: b (per $ of AUM) | AB6: =($AB$5/Inputs!$B$35)^2 -> 4.6843026e-12
A7: 5 | B7: =C6 -> 5.791546e-07 | C7: =(1/Inputs!$B$16)*(Inputs!$B$21/(1/Inputs!$B$16))^(4/60) -> 6.3393354e-07 | D7: =(B7+C7)/2 -> 6.0654407e-07 | E7: =C7-B7 -> 5.4778939e-08 | F7: =Inputs!$B$16*E7 -> 0.12404143 | G7: =IF(D7<=Inputs!$B$21,1,IF(D7<=Inputs!$B$22,2,IF(D7<=Inputs!$B$23,3,IF(D7<=Inputs!$B$24,4,5)))) -> 1 | H7: =Fit!$B$10*D7^(-1/Fit!$B$9) -> 313880.97 | I7: =EXP(Fit!$B$16+Fit!$B$15*-NORMSINV(D7)) -> 2301.8861 | J7: =Fit!$B$22*LN(1/D7)^(1/Fit!$B$21) -> 609.02056 | K7: =MAX(0,Fit!$B$28+Fit!$B$27*-NORMSINV(D7)) -> 345.97573 | L7: =INDEX(H7:K7,1,Inputs!$B$5) -> 313880.97 | M7: =L7*E7 -> 0.017194066 | N7: =L7^$AB$7 -> 313880.97 | O7: =N7*E7 -> 0.017194066 | P7: =N7*$AB$3/($AB$4*$AB$1) -> 2.1167993e+09 | Q7: =IF(G7<=3,F7*SQRT(P7),0) -> 5706.9833 | R7: =SQRT(P7/$AB$6) -> 2.1257754e+10 | S7: =2*$AB$6*R7 -> 0.1991555 | T7: =IF(G7<=3,F7*R7,0) -> 2.6368422e+09 | U7: =F7*P7 -> 2.6257081e+08 | V7: =H7^$AB$7*E7 -> 0.017194066 | W7: =I7^$AB$7*E7 -> 0.00012609488 | X7: =J7^$AB$7*E7 -> 3.33615e-05 | Y7: =K7^$AB$7*E7 -> 1.8952184e-05 | AA7: power | AB7: =Inputs!$B$6 -> 1
A8: 6 | B8: =C7 -> 6.3393354e-07 | C8: =(1/Inputs!$B$16)*(Inputs!$B$21/(1/Inputs!$B$16))^(5/60) -> 6.9389371e-07 | D8: =(B8+C8)/2 -> 6.6391362e-07 | E8: =C8-B8 -> 5.9960167e-08 | F8: =Inputs!$B$16*E8 -> 0.1357738 | G8: =IF(D8<=Inputs!$B$21,1,IF(D8<=Inputs!$B$22,2,IF(D8<=Inputs!$B$23,3,IF(D8<=Inputs!$B$24,4,5)))) -> 1 | H8: =Fit!$B$10*D8^(-1/Fit!$B$9) -> 295893.02 | I8: =EXP(Fit!$B$16+Fit!$B$15*-NORMSINV(D8)) -> 2268.2587 | J8: =Fit!$B$22*LN(1/D8)^(1/Fit!$B$21) -> 605.65342 | K8: =MAX(0,Fit!$B$28+Fit!$B$27*-NORMSINV(D8)) -> 344.85553 | L8: =INDEX(H8:K8,1,Inputs!$B$5) -> 295893.02 | M8: =L8*E8 -> 0.017741795 | N8: =L8^$AB$7 -> 295893.02 | O8: =N8*E8 -> 0.017741795 | P8: =N8*$AB$3/($AB$4*$AB$1) -> 1.9954894e+09 | Q8: =IF(G8<=3,F8*SQRT(P8),0) -> 6065.1381 | R8: =SQRT(P8/$AB$6) -> 2.0639646e+10 | S8: =2*$AB$6*R8 -> 0.19336469 | T8: =IF(G8<=3,F8*R8,0) -> 2.8023232e+09 | U8: =F8*P8 -> 2.7093518e+08 | V8: =H8^$AB$7*E8 -> 0.017741795 | W8: =I8^$AB$7*E8 -> 0.00013600517 | X8: =J8^$AB$7*E8 -> 3.631508e-05 | Y8: =K8^$AB$7*E8 -> 2.0677596e-05 | AA8: Total A* of the top 1% ($) | AB8: =SUM(T3:T303) -> 30000000000000
A9: 7 | B9: =C8 -> 6.9389371e-07 | C9: =(1/Inputs!$B$16)*(Inputs!$B$21/(1/Inputs!$B$16))^(6/60) -> 7.5952517e-07 | D9: =(B9+C9)/2 -> 7.2670944e-07 | E9: =C9-B9 -> 6.5631458e-08 | F9: =Inputs!$B$16*E9 -> 0.14861587 | G9: =IF(D9<=Inputs!$B$21,1,IF(D9<=Inputs!$B$22,2,IF(D9<=Inputs!$B$23,3,IF(D9<=Inputs!$B$24,4,5)))) -> 1 | H9: =Fit!$B$10*D9^(-1/Fit!$B$9) -> 278935.93 | I9: =EXP(Fit!$B$16+Fit!$B$15*-NORMSINV(D9)) -> 2235.0089 | J9: =Fit!$B$22*LN(1/D9)^(1/Fit!$B$21) -> 602.28361 | K9: =MAX(0,Fit!$B$28+Fit!$B$27*-NORMSINV(D9)) -> 343.73146 | L9: =INDEX(H9:K9,1,Inputs!$B$5) -> 278935.93 | M9: =L9*E9 -> 0.018306972 | N9: =L9^$AB$7 -> 278935.93 | O9: =N9*E9 -> 0.018306972 | P9: =N9*$AB$3/($AB$4*$AB$1) -> 1.8811315e+09 | Q9: =IF(G9<=3,F9*SQRT(P9),0) -> 6445.7697 | R9: =SQRT(P9/$AB$6) -> 2.0039511e+10 | S9: =2*$AB$6*R9 -> 0.18774226 | T9: =IF(G9<=3,F9*R9,0) -> 2.9781894e+09 | U9: =F9*P9 -> 2.7956601e+08 | V9: =H9^$AB$7*E9 -> 0.018306972 | W9: =I9^$AB$7*E9 -> 0.00014668689 | X9: =J9^$AB$7*E9 -> 3.9528752e-05 | Y9: =K9^$AB$7*E9 -> 2.2559597e-05
A10: 8 | B10: =C9 -> 7.5952517e-07 | C10: =(1/Inputs!$B$16)*(Inputs!$B$21/(1/Inputs!$B$16))^(7/60) -> 8.3136433e-07 | D10: =(B10+C10)/2 -> 7.9544475e-07 | E10: =C10-B10 -> 7.1839165e-08 | F10: =Inputs!$B$16*E10 -> 0.1626726 | G10: =IF(D10<=Inputs!$B$21,1,IF(D10<=Inputs!$B$22,2,IF(D10<=Inputs!$B$23,3,IF(D10<=Inputs!$B$24,4,5)))) -> 1 | H10: =Fit!$B$10*D10^(-1/Fit!$B$9) -> 262950.62 | I10: =EXP(Fit!$B$16+Fit!$B$15*-NORMSINV(D10)) -> 2202.1332 | J10: =Fit!$B$22*LN(1/D10)^(1/Fit!$B$21) -> 598.91112 | K10: =MAX(0,Fit!$B$28+Fit!$B$27*-NORMSINV(D10)) -> 342.60348 | L10: =INDEX(H10:K10,1,Inputs!$B$5) -> 262950.62 | M10: =L10*E10 -> 0.018890153 | N10: =L10^$AB$7 -> 262950.62 | O10: =N10*E10 -> 0.018890153 | P10: =N10*$AB$3/($AB$4*$AB$1) -> 1.7733273e+09 | Q10: =IF(G10<=3,F10*SQRT(P10),0) -> 6850.2887 | R10: =SQRT(P10/$AB$6) -> 1.9456825e+10 | S10: =2*$AB$6*R10 -> 0.18228332 | T10: =IF(G10<=3,F10*R10,0) -> 3.1650925e+09 | U10: =F10*P10 -> 2.8847177e+08 | V10: =H10^$AB$7*E10 -> 0.018890153 | W10: =I10^$AB$7*E10 -> 0.00015819941 | X10: =J10^$AB$7*E10 -> 4.3025274e-05 | Y10: =K10^$AB$7*E10 -> 2.4612348e-05
A11: 9 | B11: =C10 -> 8.3136433e-07 | C11: =(1/Inputs!$B$16)*(Inputs!$B$21/(1/Inputs!$B$16))^(8/60) -> 9.0999835e-07 | D11: =(B11+C11)/2 -> 8.7068134e-07 | E11: =C11-B11 -> 7.8634023e-08 | F11: =Inputs!$B$16*E11 -> 0.17805888 | G11: =IF(D11<=Inputs!$B$21,1,IF(D11<=Inputs!$B$22,2,IF(D11<=Inputs!$B$23,3,IF(D11<=Inputs!$B$24,4,5)))) -> 1 | H11: =Fit!$B$10*D11^(-1/Fit!$B$9) -> 247881.4 | I11: =EXP(Fit!$B$16+Fit!$B$15*-NORMSINV(D11)) -> 2169.6285 | J11: =Fit!$B$22*LN(1/D11)^(1/Fit!$B$21) -> 595.53592 | K11: =MAX(0,Fit!$B$28+Fit!$B$27*-NORMSINV(D11)) -> 341.47154 | L11: =INDEX(H11:K11,1,Inputs!$B$5) -> 247881.4 | M11: =L11*E11 -> 0.019491912 | N11: =L11^$AB$7 -> 247881.4 | O11: =N11*E11 -> 0.019491912 | P11: =N11*$AB$3/($AB$4*$AB$1) -> 1.6717012e+09 | Q11: =IF(G11<=3,F11*SQRT(P11),0) -> 7280.1942 | R11: =SQRT(P11/$AB$6) -> 1.8891083e+10 | S11: =2*$AB$6*R11 -> 0.1769831 | T11: =IF(G11<=3,F11*R11,0) -> 3.3637251e+09 | U11: =F11*P11 -> 2.9766124e+08 | V11: =H11^$AB$7*E11 -> 0.019491912 | W11: =I11^$AB$7*E11 -> 0.00017060661 | X11: =J11^$AB$7*E11 -> 4.6829385e-05 | Y11: =K11^$AB$7*E11 -> 2.6851281e-05
A12: 10 | B12: =C11 -> 9.0999835e-07 | C12: =(1/Inputs!$B$16)*(Inputs!$B$21/(1/Inputs!$B$16))^(9/60) -> 9.9606992e-07 | D12: =(B12+C12)/2 -> 9.5303414e-07 | E12: =C12-B12 -> 8.6071568e-08 | F12: =Inputs!$B$16*E12 -> 0.19490046 | G12: =IF(D12<=Inputs!$B$21,1,IF(D12<=Inputs!$B$22,2,IF(D12<=Inputs!$B$23,3,IF(D12<=Inputs!$B$24,4,5)))) -> 1 | H12: =Fit!$B$10*D12^(-1/Fit!$B$9) -> 233675.77 | I12: =EXP(Fit!$B$16+Fit!$B$15*-NORMSINV(D12)) -> 2137.4913 | J12: =Fit!$B$22*LN(1/D12)^(1/Fit!$B$21) -> 592.158 | K12: =MAX(0,Fit!$B$28+Fit!$B$27*-NORMSINV(D12)) -> 340.33561 | L12: =INDEX(H12:K12,1,Inputs!$B$5) -> 233675.77 | M12: =L12*E12 -> 0.02011284 | N12: =L12^$AB$7 -> 233675.77 | O12: =N12*E12 -> 0.02011284 | P12: =N12*$AB$3/($AB$4*$AB$1) -> 1.575899e+09 | Q12: =IF(G12<=3,F12*SQRT(P12),0) -> 7737.0794 | R12: =SQRT(P12/$AB$6) -> 1.834179e+10 | S12: =2*$AB$6*R12 -> 0.17183699 | T12: =IF(G12<=3,F12*R12,0) -> 3.5748233e+09 | U12: =F12*P12 -> 3.0714344e+08 | V12: =H12^$AB$7*E12 -> 0.02011284 | W12: =I12^$AB$7*E12 -> 0.00018397723 | X12: =J12^$AB$7*E12 -> 5.0967967e-05 | Y12: =K12^$AB$7*E12 -> 2.929322e-05
A13: 11 | B13: =C12 -> 9.9606992e-07 | C13: =(1/Inputs!$B$16)*(Inputs!$B$21/(1/Inputs!$B$16))^(10/60) -> 1.0902825e-06 | D13: =(B13+C13)/2 -> 1.0431762e-06 | E13: =C13-B13 -> 9.4212588e-08 | F13: =Inputs!$B$16*E13 -> 0.21333498 | G13: =IF(D13<=Inputs!$B$21,1,IF(D13<=Inputs!$B$22,2,IF(D13<=Inputs!$B$23,3,IF(D13<=Inputs!$B$24,4,5)))) -> 1 | H13: =Fit!$B$10*D13^(-1/Fit!$B$9) -> 220284.24 | I13: =EXP(Fit!$B$16+Fit!$B$15*-NORMSINV(D13)) -> 2105.7185 | J13: =Fit!$B$22*LN(1/D13)^(1/Fit!$B$21) -> 588.77733 | K13: =MAX(0,Fit!$B$28+Fit!$B$27*-NORMSINV(D13)) -> 339.19564 | L13: =INDEX(H13:K13,1,Inputs!$B$5) -> 220284.24 | M13: =L13*E13 -> 0.020753548 | N13: =L13^$AB$7 -> 220284.24 | O13: =N13*E13 -> 0.020753548 | P13: =N13*$AB$3/($AB$4*$AB$1) -> 1.4855871e+09 | Q13: =IF(G13<=3,F13*SQRT(P13),0) -> 8222.6375 | R13: =SQRT(P13/$AB$6) -> 1.7808469e+10 | S13: =2*$AB$6*R13 -> 0.16684052 | T13: =IF(G13<=3,F13*R13,0) -> 3.7991695e+09 | U13: =F13*P13 -> 3.1692771e+08 | V13: =H13^$AB$7*E13 -> 0.020753548 | W13: =I13^$AB$7*E13 -> 0.00019838519 | X13: =J13^$AB$7*E13 -> 5.5470236e-05 | Y13: =K13^$AB$7*E13 -> 3.1956499e-05
A14: 12 | B14: =C13 -> 1.0902825e-06 | C14: =(1/Inputs!$B$16)*(Inputs!$B$21/(1/Inputs!$B$16))^(11/60) -> 1.1934061e-06 | D14: =(B14+C14)/2 -> 1.1418443e-06 | E14: =C14-B14 -> 1.0312362e-07 | F14: =Inputs!$B$16*E14 -> 0.23351313 | G14: =IF(D14<=Inputs!$B$21,1,IF(D14<=Inputs!$B$22,2,IF(D14<=Inputs!$B$23,3,IF(D14<=Inputs!$B$24,4,5)))) -> 1 | H14: =Fit!$B$10*D14^(-1/Fit!$B$9) -> 207660.15 | I14: =EXP(Fit!$B$16+Fit!$B$15*-NORMSINV(D14)) -> 2074.3069 | J14: =Fit!$B$22*LN(1/D14)^(1/Fit!$B$21) -> 585.3939 | K14: =MAX(0,Fit!$B$28+Fit!$B$27*-NORMSINV(D14)) -> 338.0516 | L14: =INDEX(H14:K14,1,Inputs!$B$5) -> 207660.15 | M14: =L14*E14 -> 0.021414667 | N14: =L14^$AB$7 -> 207660.15 | O14: =N14*E14 -> 0.021414667 | P14: =N14*$AB$3/($AB$4*$AB$1) -> 1.4004508e+09 | Q14: =IF(G14<=3,F14*SQRT(P14),0) -> 8738.6678 | R14: =SQRT(P14/$AB$6) -> 1.7290656e+10 | S14: =2*$AB$6*R14 -> 0.16198933 | T14: =IF(G14<=3,F14*R14,0) -> 4.0375951e+09 | U14: =F14*P14 -> 3.2702365e+08 | V14: =H14^$AB$7*E14 -> 0.021414667 | W14: =I14^$AB$7*E14 -> 0.00021391004 | X14: =J14^$AB$7*E14 -> 6.0367939e-05 | Y14: =K14^$AB$7*E14 -> 3.4861105e-05
A15: 13 | B15: =C14 -> 1.1934061e-06 | C15: =(1/Inputs!$B$16)*(Inputs!$B$21/(1/Inputs!$B$16))^(12/60) -> 1.3062836e-06 | D15: =(B15+C15)/2 -> 1.2498449e-06 | E15: =C15-B15 -> 1.128775e-07 | F15: =Inputs!$B$16*E15 -> 0.2555998 | G15: =IF(D15<=Inputs!$B$21,1,IF(D15<=Inputs!$B$22,2,IF(D15<=Inputs!$B$23,3,IF(D15<=Inputs!$B$24,4,5)))) -> 1 | H15: =Fit!$B$10*D15^(-1/Fit!$B$9) -> 195759.53 | I15: =EXP(Fit!$B$16+Fit!$B$15*-NORMSINV(D15)) -> 2043.2532 | J15: =Fit!$B$22*LN(1/D15)^(1/Fit!$B$21) -> 582.00769 | K15: =MAX(0,Fit!$B$28+Fit!$B$27*-NORMSINV(D15)) -> 336.90343 | L15: =INDEX(H15:K15,1,Inputs!$B$5) -> 195759.53 | M15: =L15*E15 -> 0.022096845 | N15: =L15^$AB$7 -> 195759.53 | O15: =N15*E15 -> 0.022096845 | P15: =N15*$AB$3/($AB$4*$AB$1) -> 1.3201936e+09 | Q15: =IF(G15<=3,F15*SQRT(P15),0) -> 9287.0829 | R15: =SQRT(P15/$AB$6) -> 1.6787899e+10 | S15: =2*$AB$6*R15 -> 0.15727919 | T15: =IF(G15<=3,F15*R15,0) -> 4.2909836e+09 | U15: =F15*P15 -> 3.3744122e+08 | V15: =H15^$AB$7*E15 -> 0.022096845 | W15: =I15^$AB$7*E15 -> 0.00023063731 | X15: =J15^$AB$7*E15 -> 6.5695571e-05 | Y15: =K15^$AB$7*E15 -> 3.8028816e-05
A16: 14 | B16: =C15 -> 1.3062836e-06 | C16: =(1/Inputs!$B$16)*(Inputs!$B$21/(1/Inputs!$B$16))^(13/60) -> 1.4298376e-06 | D16: =(B16+C16)/2 -> 1.3680606e-06 | E16: =C16-B16 -> 1.2355394e-07 | F16: =Inputs!$B$16*E16 -> 0.27977554 | G16: =IF(D16<=Inputs!$B$21,1,IF(D16<=Inputs!$B$22,2,IF(D16<=Inputs!$B$23,3,IF(D16<=Inputs!$B$24,4,5)))) -> 1 | H16: =Fit!$B$10*D16^(-1/Fit!$B$9) -> 184540.91 | I16: =EXP(Fit!$B$16+Fit!$B$15*-NORMSINV(D16)) -> 2012.5543 | J16: =Fit!$B$22*LN(1/D16)^(1/Fit!$B$21) -> 578.61867 | K16: =MAX(0,Fit!$B$28+Fit!$B$27*-NORMSINV(D16)) -> 335.7511 | L16: =INDEX(H16:K16,1,Inputs!$B$5) -> 184540.91 | M16: =L16*E16 -> 0.022800755 | N16: =L16^$AB$7 -> 184540.91 | O16: =N16*E16 -> 0.022800755 | P16: =N16*$AB$3/($AB$4*$AB$1) -> 1.2445357e+09 | Q16: =IF(G16<=3,F16*SQRT(P16),0) -> 9869.915 | R16: =SQRT(P16/$AB$6) -> 1.629976e+10 | S16: =2*$AB$6*R16 -> 0.15270601 | T16: =IF(G16<=3,F16*R16,0) -> 4.560274e+09 | U16: =F16*P16 -> 3.4819064e+08 | V16: =H16^$AB$7*E16 -> 0.022800755 | W16: =I16^$AB$7*E16 -> 0.00024865901 | X16: =J16^$AB$7*E16 -> 7.1490615e-05 | Y16: =K16^$AB$7*E16 -> 4.148337e-05
A17: 15 | B17: =C16 -> 1.4298376e-06 | C17: =(1/Inputs!$B$16)*(Inputs!$B$21/(1/Inputs!$B$16))^(14/60) -> 1.5650778e-06 | D17: =(B17+C17)/2 -> 1.4974577e-06 | E17: =C17-B17 -> 1.352402e-07 | F17: =Inputs!$B$16*E17 -> 0.30623791 | G17: =IF(D17<=Inputs!$B$21,1,IF(D17<=Inputs!$B$22,2,IF(D17<=Inputs!$B$23,3,IF(D17<=Inputs!$B$24,4,5)))) -> 1 | H17: =Fit!$B$10*D17^(-1/Fit!$B$9) -> 173965.2 | I17: =EXP(Fit!$B$16+Fit!$B$15*-NORMSINV(D17)) -> 1982.207 | J17: =Fit!$B$22*LN(1/D17)^(1/Fit!$B$21) -> 575.22682 | K17: =MAX(0,Fit!$B$28+Fit!$B$27*-NORMSINV(D17)) -> 334.59455 | L17: =INDEX(H17:K17,1,Inputs!$B$5) -> 173965.2 | M17: =L17*E17 -> 0.023527089 | N17: =L17^$AB$7 -> 173965.2 | O17: =N17*E17 -> 0.023527089 | P17: =N17*$AB$3/($AB$4*$AB$1) -> 1.1732136e+09 | Q17: =IF(G17<=3,F17*SQRT(P17),0) -> 10489.324 | R17: =SQRT(P17/$AB$6) -> 1.5825815e+10 | S17: =2*$AB$6*R17 -> 0.14826581 | T17: =IF(G17<=3,F17*R17,0) -> 4.8464644e+09 | U17: =F17*P17 -> 3.5928249e+08 | V17: =H17^$AB$7*E17 -> 0.023527089 | W17: =I17^$AB$7*E17 -> 0.00026807407 | X17: =J17^$AB$7*E17 -> 7.7793791e-05 | Y17: =K17^$AB$7*E17 -> 4.5250635e-05
A18: 16 | B18: =C17 -> 1.5650778e-06 | C18: =(1/Inputs!$B$16)*(Inputs!$B$21/(1/Inputs!$B$16))^(15/60) -> 1.7131096e-06 | D18: =(B18+C18)/2 -> 1.6390937e-06 | E18: =C18-B18 -> 1.480318e-07 | F18: =Inputs!$B$16*E18 -> 0.33520321 | G18: =IF(D18<=Inputs!$B$21,1,IF(D18<=Inputs!$B$22,2,IF(D18<=Inputs!$B$23,3,IF(D18<=Inputs!$B$24,4,5)))) -> 1 | H18: =Fit!$B$10*D18^(-1/Fit!$B$9) -> 163995.57 | I18: =EXP(Fit!$B$16+Fit!$B$15*-NORMSINV(D18)) -> 1952.2081 | J18: =Fit!$B$22*LN(1/D18)^(1/Fit!$B$21) -> 571.83212 | K18: =MAX(0,Fit!$B$28+Fit!$B$27*-NORMSINV(D18)) -> 333.43376 | L18: =INDEX(H18:K18,1,Inputs!$B$5) -> 163995.57 | M18: =L18*E18 -> 0.024276561 | N18: =L18^$AB$7 -> 163995.57 | O18: =N18*E18 -> 0.024276561 | P18: =N18*$AB$3/($AB$4*$AB$1) -> 1.1059789e+09 | Q18: =IF(G18<=3,F18*SQRT(P18),0) -> 11147.605 | R18: =SQRT(P18/$AB$6) -> 1.536565e+10 | S18: =2*$AB$6*R18 -> 0.14395471 | T18: =IF(G18<=3,F18*R18,0) -> 5.1506154e+09 | U18: =F18*P18 -> 3.7072767e+08 | V18: =H18^$AB$7*E18 -> 0.024276561 | W18: =I18^$AB$7*E18 -> 0.00028898888 | X18: =J18^$AB$7*E18 -> 8.464934e-05 | Y18: =K18^$AB$7*E18 -> 4.93588e-05
A19: 17 | B19: =C18 -> 1.7131096e-06 | C19: =(1/Inputs!$B$16)*(Inputs!$B$21/(1/Inputs!$B$16))^(16/60) -> 1.8751429e-06 | D19: =(B19+C19)/2 -> 1.7941262e-06 | E19: =C19-B19 -> 1.6203329e-07 | F19: =Inputs!$B$16*E19 -> 0.36690818 | G19: =IF(D19<=Inputs!$B$21,1,IF(D19<=Inputs!$B$22,2,IF(D19<=Inputs!$B$23,3,IF(D19<=Inputs!$B$24,4,5)))) -> 1 | H19: =Fit!$B$10*D19^(-1/Fit!$B$9) -> 154597.29 | I19: =EXP(Fit!$B$16+Fit!$B$15*-NORMSINV(D19)) -> 1922.5546 | J19: =Fit!$B$22*LN(1/D19)^(1/Fit!$B$21) -> 568.43456 | K19: =MAX(0,Fit!$B$28+Fit!$B$27*-NORMSINV(D19)) -> 332.26866 | L19: =INDEX(H19:K19,1,Inputs!$B$5) -> 154597.29 | M19: =L19*E19 -> 0.025049907 | N19: =L19^$AB$7 -> 154597.29 | O19: =N19*E19 -> 0.025049907 | P19: =N19*$AB$3/($AB$4*$AB$1) -> 1.0425972e+09 | Q19: =IF(G19<=3,F19*SQRT(P19),0) -> 11847.199 | R19: =SQRT(P19/$AB$6) -> 1.4918866e+10 | S19: =2*$AB$6*R19 -> 0.13976897 | T19: =IF(G19<=3,F19*R19,0) -> 5.473854e+09 | U19: =F19*P19 -> 3.8253746e+08 | V19: =H19^$AB$7*E19 -> 0.025049907 | W19: =I19^$AB$7*E19 -> 0.00031151784 | X19: =J19^$AB$7*E19 -> 9.210532e-05 | Y19: =K19^$AB$7*E19 -> 5.3838583e-05
A20: 18 | B20: =C19 -> 1.8751429e-06 | C20: =(1/Inputs!$B$16)*(Inputs!$B$21/(1/Inputs!$B$16))^(17/60) -> 2.052502e-06 | D20: =(B20+C20)/2 -> 1.9638224e-06 | E20: =C20-B20 -> 1.773591e-07 | F20: =Inputs!$B$16*E20 -> 0.40161194 | G20: =IF(D20<=Inputs!$B$21,1,IF(D20<=Inputs!$B$22,2,IF(D20<=Inputs!$B$23,3,IF(D20<=Inputs!$B$24,4,5)))) -> 1 | H20: =Fit!$B$10*D20^(-1/Fit!$B$9) -> 145737.6 | I20: =EXP(Fit!$B$16+Fit!$B$15*-NORMSINV(D20)) -> 1893.2433 | J20: =Fit!$B$22*LN(1/D20)^(1/Fit!$B$21) -> 565.0341 | K20: =MAX(0,Fit!$B$28+Fit!$B$27*-NORMSINV(D20)) -> 331.09921 | L20: =INDEX(H20:K20,1,Inputs!$B$5) -> 145737.6 | M20: =L20*E20 -> 0.025847889 | N20: =L20^$AB$7 -> 145737.6 | O20: =N20*E20 -> 0.025847889 | P20: =N20*$AB$3/($AB$4*$AB$1) -> 9.828479e+08 | Q20: =IF(G20<=3,F20*SQRT(P20),0) -> 12590.697 | R20: =SQRT(P20/$AB$6) -> 1.4485073e+10 | S20: =2*$AB$6*R20 -> 0.13570493 | T20: =IF(G20<=3,F20*R20,0) -> 5.8173782e+09 | U20: =F20*P20 -> 3.9472345e+08 | V20: =H20^$AB$7*E20 -> 0.025847889 | W20: =I20^$AB$7*E20 -> 0.00033578392 | X20: =J20^$AB$7*E20 -> 0.00010021394 | Y20: =K20^$AB$7*E20 -> 5.8723456e-05
A21: 19 | B21: =C20 -> 2.052502e-06 | C21: =(1/Inputs!$B$16)*(Inputs!$B$21/(1/Inputs!$B$16))^(18/60) -> 2.2466364e-06 | D21: =(B21+C21)/2 -> 2.1495692e-06 | E21: =C21-B21 -> 1.9413448e-07 | F21: =Inputs!$B$16*E21 -> 0.43959812 | G21: =IF(D21<=Inputs!$B$21,1,IF(D21<=Inputs!$B$22,2,IF(D21<=Inputs!$B$23,3,IF(D21<=Inputs!$B$24,4,5)))) -> 1 | H21: =Fit!$B$10*D21^(-1/Fit!$B$9) -> 137385.64 | I21: =EXP(Fit!$B$16+Fit!$B$15*-NORMSINV(D21)) -> 1864.2713 | J21: =Fit!$B$22*LN(1/D21)^(1/Fit!$B$21) -> 561.63072 | K21: =MAX(0,Fit!$B$28+Fit!$B$27*-NORMSINV(D21)) -> 329.92536 | L21: =INDEX(H21:K21,1,Inputs!$B$5) -> 137385.64 | M21: =L21*E21 -> 0.026671291 | N21: =L21^$AB$7 -> 137385.64 | O21: =N21*E21 -> 0.026671291 | P21: =N21*$AB$3/($AB$4*$AB$1) -> 9.2652268e+08 | Q21: =IF(G21<=3,F21*SQRT(P21),0) -> 13380.855 | R21: =SQRT(P21/$AB$6) -> 1.4063893e+10 | S21: =2*$AB$6*R21 -> 0.13175906 | T21: =IF(G21<=3,F21*R21,0) -> 6.1824611e+09 | U21: =F21*P21 -> 4.0729763e+08 | V21: =H21^$AB$7*E21 -> 0.026671291 | W21: =I21^$AB$7*E21 -> 0.00036191934 | X21: =J21^$AB$7*E21 -> 0.00010903189 | Y21: =K21^$AB$7*E21 -> 6.4049889e-05
A22: 20 | B22: =C21 -> 2.2466364e-06 | C22: =(1/Inputs!$B$16)*(Inputs!$B$21/(1/Inputs!$B$16))^(19/60) -> 2.459133e-06 | D22: =(B22+C22)/2 -> 2.3528847e-06 | E22: =C22-B22 -> 2.1249656e-07 | F22: =Inputs!$B$16*E22 -> 0.48117721 | G22: =IF(D22<=Inputs!$B$21,1,IF(D22<=Inputs!$B$22,2,IF(D22<=Inputs!$B$23,3,IF(D22<=Inputs!$B$24,4,5)))) -> 1 | H22: =Fit!$B$10*D22^(-1/Fit!$B$9) -> 129512.32 | I22: =EXP(Fit!$B$16+Fit!$B$15*-NORMSINV(D22)) -> 1835.6353 | J22: =Fit!$B$22*LN(1/D22)^(1/Fit!$B$21) -> 558.22441 | K22: =MAX(0,Fit!$B$28+Fit!$B$27*-NORMSINV(D22)) -> 328.74707 | L22: =INDEX(H22:K22,1,Inputs!$B$5) -> 129512.32 | M22: =L22*E22 -> 0.027520923 | N22: =L22^$AB$7 -> 129512.32 | O22: =N22*E22 -> 0.027520923 | P22: =N22*$AB$3/($AB$4*$AB$1) -> 8.7342536e+08 | Q22: =IF(G22<=3,F22*SQRT(P22),0) -> 14220.601 | R22: =SQRT(P22/$AB$6) -> 1.365496e+10 | S22: =2*$AB$6*R22 -> 0.12792793 | T22: =IF(G22<=3,F22*R22,0) -> 6.5704555e+09 | U22: =F22*P22 -> 4.2027238e+08 | V22: =H22^$AB$7*E22 -> 0.027520923 | W22: =I22^$AB$7*E22 -> 0.0003900662 | X22: =J22^$AB$7*E22 -> 0.00011862077 | Y22: =K22^$AB$7*E22 -> 6.9857621e-05
A23: 21 | B23: =C22 -> 2.459133e-06 | C23: =(1/Inputs!$B$16)*(Inputs!$B$21/(1/Inputs!$B$16))^(20/60) -> 2.6917284e-06 | D23: =(B23+C23)/2 -> 2.5754307e-06 | E23: =C23-B23 -> 2.325954e-07 | F23: =Inputs!$B$16*E23 -> 0.52668903 | G23: =IF(D23<=Inputs!$B$21,1,IF(D23<=Inputs!$B$22,2,IF(D23<=Inputs!$B$23,3,IF(D23<=Inputs!$B$24,4,5)))) -> 1 | H23: =Fit!$B$10*D23^(-1/Fit!$B$9) -> 122090.21 | I23: =EXP(Fit!$B$16+Fit!$B$15*-NORMSINV(D23)) -> 1807.3325 | J23: =Fit!$B$22*LN(1/D23)^(1/Fit!$B$21) -> 554.81514 | K23: =MAX(0,Fit!$B$28+Fit!$B$27*-NORMSINV(D23)) -> 327.56428 | L23: =INDEX(H23:K23,1,Inputs!$B$5) -> 122090.21 | M23: =L23*E23 -> 0.028397621 | N23: =L23^$AB$7 -> 122090.21 | O23: =N23*E23 -> 0.028397621 | P23: =N23*$AB$3/($AB$4*$AB$1) -> 8.2337095e+08 | Q23: =IF(G23<=3,F23*SQRT(P23),0) -> 15113.047 | R23: =SQRT(P23/$AB$6) -> 1.3257917e+10 | S23: =2*$AB$6*R23 -> 0.12420819 | T23: =IF(G23<=3,F23*R23,0) -> 6.9827994e+09 | U23: =F23*P23 -> 4.3366044e+08 | V23: =H23^$AB$7*E23 -> 0.028397621 | W23: =I23^$AB$7*E23 -> 0.00042037724 | X23: =J23^$AB$7*E23 -> 0.00012904745 | Y23: =K23^$AB$7*E23 -> 7.6189945e-05
A24: 22 | B24: =C23 -> 2.6917284e-06 | C24: =(1/Inputs!$B$16)*(Inputs!$B$21/(1/Inputs!$B$16))^(21/60) -> 2.9463237e-06 | D24: =(B24+C24)/2 -> 2.819026e-06 | E24: =C24-B24 -> 2.5459528e-07 | F24: =Inputs!$B$16*E24 -> 0.57650554 | G24: =IF(D24<=Inputs!$B$21,1,IF(D24<=Inputs!$B$22,2,IF(D24<=Inputs!$B$23,3,IF(D24<=Inputs!$B$24,4,5)))) -> 1 | H24: =Fit!$B$10*D24^(-1/Fit!$B$9) -> 115093.44 | I24: =EXP(Fit!$B$16+Fit!$B$15*-NORMSINV(D24)) -> 1779.3599 | J24: =Fit!$B$22*LN(1/D24)^(1/Fit!$B$21) -> 551.40288 | K24: =MAX(0,Fit!$B$28+Fit!$B$27*-NORMSINV(D24)) -> 326.37695 | L24: =INDEX(H24:K24,1,Inputs!$B$5) -> 115093.44 | M24: =L24*E24 -> 0.029302246 | N24: =L24^$AB$7 -> 115093.44 | O24: =N24*E24 -> 0.029302246 | P24: =N24*$AB$3/($AB$4*$AB$1) -> 7.7618506e+08 | Q24: =IF(G24<=3,F24*SQRT(P24),0) -> 16061.501 | R24: =SQRT(P24/$AB$6) -> 1.2872419e+10 | S24: =2*$AB$6*R24 -> 0.12059661 | T24: =IF(G24<=3,F24*R24,0) -> 7.421021e+09 | U24: =F24*P24 -> 4.4747499e+08 | V24: =H24^$AB$7*E24 -> 0.029302246 | W24: =I24^$AB$7*E24 -> 0.00045301662 | X24: =J24^$AB$7*E24 -> 0.00014038457 | Y24: =K24^$AB$7*E24 -> 8.3094029e-05
A25: 23 | B25: =C24 -> 2.9463237e-06 | C25: =(1/Inputs!$B$16)*(Inputs!$B$21/(1/Inputs!$B$16))^(22/60) -> 3.2249997e-06 | D25: =(B25+C25)/2 -> 3.0856617e-06 | E25: =C25-B25 -> 2.78676e-07 | F25: =Inputs!$B$16*E25 -> 0.63103392 | G25: =IF(D25<=Inputs!$B$21,1,IF(D25<=Inputs!$B$22,2,IF(D25<=Inputs!$B$23,3,IF(D25<=Inputs!$B$24,4,5)))) -> 1 | H25: =Fit!$B$10*D25^(-1/Fit!$B$9) -> 108497.65 | I25: =EXP(Fit!$B$16+Fit!$B$15*-NORMSINV(D25)) -> 1751.7143 | J25: =Fit!$B$22*LN(1/D25)^(1/Fit!$B$21) -> 547.98762 | K25: =MAX(0,Fit!$B$28+Fit!$B$27*-NORMSINV(D25)) -> 325.18502 | L25: =INDEX(H25:K25,1,Inputs!$B$5) -> 108497.65 | M25: =L25*E25 -> 0.030235689 | N25: =L25^$AB$7 -> 108497.65 | O25: =N25*E25 -> 0.030235689 | P25: =N25*$AB$3/($AB$4*$AB$1) -> 7.3170331e+08 | Q25: =IF(G25<=3,F25*SQRT(P25),0) -> 17069.477 | R25: =SQRT(P25/$AB$6) -> 1.249813e+10 | S25: =2*$AB$6*R25 -> 0.11709005 | T25: =IF(G25<=3,F25*R25,0) -> 7.8867441e+09 | U25: =F25*P25 -> 4.6172961e+08 | V25: =H25^$AB$7*E25 -> 0.030235689 | W25: =I25^$AB$7*E25 -> 0.00048816073 | X25: =J25^$AB$7*E25 -> 0.000152711 | Y25: =K25^$AB$7*E25 -> 9.0621259e-05
A26: 24 | B26: =C25 -> 3.2249997e-06 | C26: =(1/Inputs!$B$16)*(Inputs!$B$21/(1/Inputs!$B$16))^(23/60) -> 3.530034e-06 | D26: =(B26+C26)/2 -> 3.3775169e-06 | E26: =C26-B26 -> 3.0503437e-07 | F26: =Inputs!$B$16*E26 -> 0.69071983 | G26: =IF(D26<=Inputs!$B$21,1,IF(D26<=Inputs!$B$22,2,IF(D26<=Inputs!$B$23,3,IF(D26<=Inputs!$B$24,4,5)))) -> 1 | H26: =Fit!$B$10*D26^(-1/Fit!$B$9) -> 102279.84 | I26: =EXP(Fit!$B$16+Fit!$B$15*-NORMSINV(D26)) -> 1724.3929 | J26: =Fit!$B$22*LN(1/D26)^(1/Fit!$B$21) -> 544.56932 | K26: =MAX(0,Fit!$B$28+Fit!$B$27*-NORMSINV(D26)) -> 323.98844 | L26: =INDEX(H26:K26,1,Inputs!$B$5) -> 102279.84 | M26: =L26*E26 -> 0.031198868 | N26: =L26^$AB$7 -> 102279.84 | O26: =N26*E26 -> 0.031198868 | P26: =N26*$AB$3/($AB$4*$AB$1) -> 6.8977073e+08 | Q26: =IF(G26<=3,F26*SQRT(P26),0) -> 18140.711 | R26: =SQRT(P26/$AB$6) -> 1.2134724e+10 | S26: =2*$AB$6*R26 -> 0.11368544 | T26: =IF(G26<=3,F26*R26,0) -> 8.3816947e+09 | U26: =F26*P26 -> 4.7643832e+08 | V26: =H26^$AB$7*E26 -> 0.031198868 | W26: =I26^$AB$7*E26 -> 0.00052599912 | X26: =J26^$AB$7*E26 -> 0.00016611236 | Y26: =K26^$AB$7*E26 -> 9.882761e-05
A27: 25 | B27: =C26 -> 3.530034e-06 | C27: =(1/Inputs!$B$16)*(Inputs!$B$21/(1/Inputs!$B$16))^(24/60) -> 3.8639199e-06 | D27: =(B27+C27)/2 -> 3.696977e-06 | E27: =C27-B27 -> 3.3388584e-07 | F27: =Inputs!$B$16*E27 -> 0.75605109 | G27: =IF(D27<=Inputs!$B$21,1,IF(D27<=Inputs!$B$22,2,IF(D27<=Inputs!$B$23,3,IF(D27<=Inputs!$B$24,4,5)))) -> 1 | H27: =Fit!$B$10*D27^(-1/Fit!$B$9) -> 96418.373 | I27: =EXP(Fit!$B$16+Fit!$B$15*-NORMSINV(D27)) -> 1697.3928 | J27: =Fit!$B$22*LN(1/D27)^(1/Fit!$B$21) -> 541.14797 | K27: =MAX(0,Fit!$B$28+Fit!$B$27*-NORMSINV(D27)) -> 322.78715 | L27: =INDEX(H27:K27,1,Inputs!$B$5) -> 96418.373 | M27: =L27*E27 -> 0.032192729 | N27: =L27^$AB$7 -> 96418.373 | O27: =N27*E27 -> 0.032192729 | P27: =N27*$AB$3/($AB$4*$AB$1) -> 6.5024123e+08 | Q27: =IF(G27<=3,F27*SQRT(P27),0) -> 19279.173 | R27: =SQRT(P27/$AB$6) -> 1.1781885e+10 | S27: =2*$AB$6*R27 -> 0.11037983 | T27: =IF(G27<=3,F27*R27,0) -> 8.9077071e+09 | U27: =F27*P27 -> 4.9161559e+08 | V27: =H27^$AB$7*E27 -> 0.032192729 | W27: =I27^$AB$7*E27 -> 0.00056673542 | X27: =J27^$AB$7*E27 -> 0.00018068164 | Y27: =K27^$AB$7*E27 -> 0.00010777406
A28: 26 | B28: =C27 -> 3.8639199e-06 | C28: =(1/Inputs!$B$16)*(Inputs!$B$21/(1/Inputs!$B$16))^(25/60) -> 4.2293861e-06 | D28: =(B28+C28)/2 -> 4.046653e-06 | E28: =C28-B28 -> 3.654662e-07 | F28: =Inputs!$B$16*E28 -> 0.82756166 | G28: =IF(D28<=Inputs!$B$21,1,IF(D28<=Inputs!$B$22,2,IF(D28<=Inputs!$B$23,3,IF(D28<=Inputs!$B$24,4,5)))) -> 1 | H28: =Fit!$B$10*D28^(-1/Fit!$B$9) -> 90892.812 | I28: =EXP(Fit!$B$16+Fit!$B$15*-NORMSINV(D28)) -> 1670.711 | J28: =Fit!$B$22*LN(1/D28)^(1/Fit!$B$21) -> 537.72354 | K28: =MAX(0,Fit!$B$28+Fit!$B$27*-NORMSINV(D28)) -> 321.58111 | L28: =INDEX(H28:K28,1,Inputs!$B$5) -> 90892.812 | M28: =L28*E28 -> 0.033218251 | N28: =L28^$AB$7 -> 90892.812 | O28: =N28*E28 -> 0.033218251 | P28: =N28*$AB$3/($AB$4*$AB$1) -> 6.1297709e+08 | Q28: =IF(G28<=3,F28*SQRT(P28),0) -> 20489.081 | R28: =SQRT(P28/$AB$6) -> 1.1439305e+10 | S28: =2*$AB$6*R28 -> 0.10717033 | T28: =IF(G28<=3,F28*R28,0) -> 9.4667305e+09 | U28: =F28*P28 -> 5.0727634e+08 | V28: =H28^$AB$7*E28 -> 0.033218251 | W28: =I28^$AB$7*E28 -> 0.0006105884 | X28: =J28^$AB$7*E28 -> 0.00019651978 | Y28: =K28^$AB$7*E28 -> 0.00011752703
A29: 27 | B29: =C28 -> 4.2293861e-06 | C29: =(1/Inputs!$B$16)*(Inputs!$B$21/(1/Inputs!$B$16))^(26/60) -> 4.6294196e-06 | D29: =(B29+C29)/2 -> 4.4294029e-06 | E29: =C29-B29 -> 4.0003357e-07 | F29: =Inputs!$B$16*E29 -> 0.90583601 | G29: =IF(D29<=Inputs!$B$21,1,IF(D29<=Inputs!$B$22,2,IF(D29<=Inputs!$B$23,3,IF(D29<=Inputs!$B$24,4,5)))) -> 1 | H29: =Fit!$B$10*D29^(-1/Fit!$B$9) -> 85683.911 | I29: =EXP(Fit!$B$16+Fit!$B$15*-NORMSINV(D29)) -> 1644.3446 | J29: =Fit!$B$22*LN(1/D29)^(1/Fit!$B$21) -> 534.296 | K29: =MAX(0,Fit!$B$28+Fit!$B$27*-NORMSINV(D29)) -> 320.37025 | L29: =INDEX(H29:K29,1,Inputs!$B$5) -> 85683.911 | M29: =L29*E29 -> 0.034276441 | N29: =L29^$AB$7 -> 85683.911 | O29: =N29*E29 -> 0.034276441 | P29: =N29*$AB$3/($AB$4*$AB$1) -> 5.7784849e+08 | Q29: =IF(G29<=3,F29*SQRT(P29),0) -> 21774.92 | R29: =SQRT(P29/$AB$6) -> 1.1106687e+10 | S29: =2*$AB$6*R29 -> 0.10405416 | T29: =IF(G29<=3,F29*R29,0) -> 1.0060837e+10 | U29: =F29*P29 -> 5.2343597e+08 | V29: =H29^$AB$7*E29 -> 0.034276441 | W29: =I29^$AB$7*E29 -> 0.00065779304 | X29: =J29^$AB$7*E29 -> 0.00021373634 | Y29: =K29^$AB$7*E29 -> 0.00012815886
A30: 28 | B30: =C29 -> 4.6294196e-06 | C30: =(1/Inputs!$B$16)*(Inputs!$B$21/(1/Inputs!$B$16))^(27/60) -> 5.0672901e-06 | D30: =(B30+C30)/2 -> 4.8483549e-06 | E30: =C30-B30 -> 4.3787047e-07 | F30: =Inputs!$B$16*E30 -> 0.99151389 | G30: =IF(D30<=Inputs!$B$21,1,IF(D30<=Inputs!$B$22,2,IF(D30<=Inputs!$B$23,3,IF(D30<=Inputs!$B$24,4,5)))) -> 1 | H30: =Fit!$B$10*D30^(-1/Fit!$B$9) -> 80773.522 | I30: =EXP(Fit!$B$16+Fit!$B$15*-NORMSINV(D30)) -> 1618.2908 | J30: =Fit!$B$22*LN(1/D30)^(1/Fit!$B$21) -> 530.86533 | K30: =MAX(0,Fit!$B$28+Fit!$B$27*-NORMSINV(D30)) -> 319.15452 | L30: =INDEX(H30:K30,1,Inputs!$B$5) -> 80773.522 | M30: =L30*E30 -> 0.03536834 | N30: =L30^$AB$7 -> 80773.522 | O30: =N30*E30 -> 0.03536834 | P30: =N30*$AB$3/($AB$4*$AB$1) -> 5.4473305e+08 | Q30: =IF(G30<=3,F30*SQRT(P30),0) -> 23141.455 | R30: =SQRT(P30/$AB$6) -> 1.078374e+10 | S30: =2*$AB$6*R30 -> 0.1010286 | T30: =IF(G30<=3,F30*R30,0) -> 1.0692228e+10 | U30: =F30*P30 -> 5.4011038e+08 | V30: =H30^$AB$7*E30 -> 0.03536834 | W30: =I30^$AB$7*E30 -> 0.00070860173 | X30: =J30^$AB$7*E30 -> 0.00023245025 | Y30: =K30^$AB$7*E30 -> 0.00013974834
A31: 29 | B31: =C30 -> 5.0672901e-06 | C31: =(1/Inputs!$B$16)*(Inputs!$B$21/(1/Inputs!$B$16))^(28/60) -> 5.5465763e-06 | D31: =(B31+C31)/2 -> 5.3069332e-06 | E31: =C31-B31 -> 4.7928615e-07 | F31: =Inputs!$B$16*E31 -> 1.0852955 | G31: =IF(D31<=Inputs!$B$21,1,IF(D31<=Inputs!$B$22,2,IF(D31<=Inputs!$B$23,3,IF(D31<=Inputs!$B$24,4,5)))) -> 1 | H31: =Fit!$B$10*D31^(-1/Fit!$B$9) -> 76144.539 | I31: =EXP(Fit!$B$16+Fit!$B$15*-NORMSINV(D31)) -> 1592.5466 | J31: =Fit!$B$22*LN(1/D31)^(1/Fit!$B$21) -> 527.4315 | K31: =MAX(0,Fit!$B$28+Fit!$B$27*-NORMSINV(D31)) -> 317.93387 | L31: =INDEX(H31:K31,1,Inputs!$B$5) -> 76144.539 | M31: =L31*E31 -> 0.036495023 | N31: =L31^$AB$7 -> 76144.539 | O31: =N31*E31 -> 0.036495023 | P31: =N31*$AB$3/($AB$4*$AB$1) -> 5.1351539e+08 | Q31: =IF(G31<=3,F31*SQRT(P31),0) -> 24593.75 | R31: =SQRT(P31/$AB$6) -> 1.0470183e+10 | S31: =2*$AB$6*R31 -> 0.098091008 | T31: =IF(G31<=3,F31*R31,0) -> 1.1363243e+10 | U31: =F31*P31 -> 5.5731597e+08 | V31: =H31^$AB$7*E31 -> 0.036495023 | W31: =I31^$AB$7*E31 -> 0.00076328553 | X31: =J31^$AB$7*E31 -> 0.00025279061 | Y31: =K31^$AB$7*E31 -> 0.0001523813
A32: 30 | B32: =C31 -> 5.5465763e-06 | C32: =(1/Inputs!$B$16)*(Inputs!$B$21/(1/Inputs!$B$16))^(29/60) -> 6.0711954e-06 | D32: =(B32+C32)/2 -> 5.8088858e-06 | E32: =C32-B32 -> 5.246191e-07 | F32: =Inputs!$B$16*E32 -> 1.1879475 | G32: =IF(D32<=Inputs!$B$21,1,IF(D32<=Inputs!$B$22,2,IF(D32<=Inputs!$B$23,3,IF(D32<=Inputs!$B$24,4,5)))) -> 1 | H32: =Fit!$B$10*D32^(-1/Fit!$B$9) -> 71780.834 | I32: =EXP(Fit!$B$16+Fit!$B$15*-NORMSINV(D32)) -> 1567.1093 | J32: =Fit!$B$22*LN(1/D32)^(1/Fit!$B$21) -> 523.99449 | K32: =MAX(0,Fit!$B$28+Fit!$B$27*-NORMSINV(D32)) -> 316.70823 | L32: =INDEX(H32:K32,1,Inputs!$B$5) -> 71780.834 | M32: =L32*E32 -> 0.037657596 | N32: =L32^$AB$7 -> 71780.834 | O32: =N32*E32 -> 0.037657596 | P32: =N32*$AB$3/($AB$4*$AB$1) -> 4.8408676e+08 | Q32: =IF(G32<=3,F32*SQRT(P32),0) -> 26137.187 | R32: =SQRT(P32/$AB$6) -> 1.0165743e+10 | S32: =2*$AB$6*R32 -> 0.095238834 | T32: =IF(G32<=3,F32*R32,0) -> 1.2076369e+10 | U32: =F32*P32 -> 5.7506965e+08 | V32: =H32^$AB$7*E32 -> 0.037657596 | W32: =I32^$AB$7*E32 -> 0.00082213547 | X32: =J32^$AB$7*E32 -> 0.00027489752 | Y32: =K32^$AB$7*E32 -> 0.00016615118
A33: 31 | B33: =C32 -> 6.0711954e-06 | C33: =(1/Inputs!$B$16)*(Inputs!$B$21/(1/Inputs!$B$16))^(30/60) -> 6.6454352e-06 | D33: =(B33+C33)/2 -> 6.3583153e-06 | E33: =C33-B33 -> 5.7423983e-07 | F33: =Inputs!$B$16*E33 -> 1.3003087 | G33: =IF(D33<=Inputs!$B$21,1,IF(D33<=Inputs!$B$22,2,IF(D33<=Inputs!$B$23,3,IF(D33<=Inputs!$B$24,4,5)))) -> 1 | H33: =Fit!$B$10*D33^(-1/Fit!$B$9) -> 67667.206 | I33: =EXP(Fit!$B$16+Fit!$B$15*-NORMSINV(D33)) -> 1541.9761 | J33: =Fit!$B$22*LN(1/D33)^(1/Fit!$B$21) -> 520.55426 | K33: =MAX(0,Fit!$B$28+Fit!$B$27*-NORMSINV(D33)) -> 315.47753 | L33: =INDEX(H33:K33,1,Inputs!$B$5) -> 67667.206 | M33: =L33*E33 -> 0.038857205 | N33: =L33^$AB$7 -> 67667.206 | O33: =N33*E33 -> 0.038857205 | P33: =N33*$AB$3/($AB$4*$AB$1) -> 4.5634463e+08 | Q33: =IF(G33<=3,F33*SQRT(P33),0) -> 27777.486 | R33: =SQRT(P33/$AB$6) -> 9.8701557e+09 | S33: =2*$AB$6*R33 -> 0.092469591 | T33: =IF(G33<=3,F33*R33,0) -> 1.2834249e+10 | U33: =F33*P33 -> 5.9338888e+08 | V33: =H33^$AB$7*E33 -> 0.038857205 | W33: =I33^$AB$7*E33 -> 0.00088546408 | X33: =J33^$AB$7*E33 -> 0.00029892299 | Y33: =K33^$AB$7*E33 -> 0.00018115977
A34: 32 | B34: =C33 -> 6.6454352e-06 | C34: =(1/Inputs!$B$16)*(Inputs!$B$21/(1/Inputs!$B$16))^(31/60) -> 7.2739891e-06 | D34: =(B34+C34)/2 -> 6.9597121e-06 | E34: =C34-B34 -> 6.2855391e-07 | F34: =Inputs!$B$16*E34 -> 1.4232975 | G34: =IF(D34<=Inputs!$B$21,1,IF(D34<=Inputs!$B$22,2,IF(D34<=Inputs!$B$23,3,IF(D34<=Inputs!$B$24,4,5)))) -> 1 | H34: =Fit!$B$10*D34^(-1/Fit!$B$9) -> 63789.322 | I34: =EXP(Fit!$B$16+Fit!$B$15*-NORMSINV(D34)) -> 1517.1441 | J34: =Fit!$B$22*LN(1/D34)^(1/Fit!$B$21) -> 517.1108 | K34: =MAX(0,Fit!$B$28+Fit!$B$27*-NORMSINV(D34)) -> 314.24173 | L34: =INDEX(H34:K34,1,Inputs!$B$5) -> 63789.322 | M34: =L34*E34 -> 0.040095028 | N34: =L34^$AB$7 -> 63789.322 | O34: =N34*E34 -> 0.040095028 | P34: =N34*$AB$3/($AB$4*$AB$1) -> 4.3019235e+08 | Q34: =IF(G34<=3,F34*SQRT(P34),0) -> 29520.725 | R34: =SQRT(P34/$AB$6) -> 9.583163e+09 | S34: =2*$AB$6*R34 -> 0.08978087 | T34: =IF(G34<=3,F34*R34,0) -> 1.3639692e+10 | U34: =F34*P34 -> 6.1229169e+08 | V34: =H34^$AB$7*E34 -> 0.040095028 | W34: =I34^$AB$7*E34 -> 0.00095360686 | X34: =J34^$AB$7*E34 -> 0.00032503202 | Y34: =K34^$AB$7*E34 -> 0.00019751787
A35: 33 | B35: =C34 -> 7.2739891e-06 | C35: =(1/Inputs!$B$16)*(Inputs!$B$21/(1/Inputs!$B$16))^(32/60) -> 7.9619944e-06 | D35: =(B35+C35)/2 -> 7.6179917e-06 | E35: =C35-B35 -> 6.8800525e-07 | F35: =Inputs!$B$16*E35 -> 1.5579191 | G35: =IF(D35<=Inputs!$B$21,1,IF(D35<=Inputs!$B$22,2,IF(D35<=Inputs!$B$23,3,IF(D35<=Inputs!$B$24,4,5)))) -> 1 | H35: =Fit!$B$10*D35^(-1/Fit!$B$9) -> 60133.672 | I35: =EXP(Fit!$B$16+Fit!$B$15*-NORMSINV(D35)) -> 1492.6106 | J35: =Fit!$B$22*LN(1/D35)^(1/Fit!$B$21) -> 513.66407 | K35: =MAX(0,Fit!$B$28+Fit!$B$27*-NORMSINV(D35)) -> 313.00076 | L35: =INDEX(H35:K35,1,Inputs!$B$5) -> 60133.672 | M35: =L35*E35 -> 0.041372282 | N35: =L35^$AB$7 -> 60133.672 | O35: =N35*E35 -> 0.041372282 | P35: =N35*$AB$3/($AB$4*$AB$1) -> 4.0553882e+08 | Q35: =IF(G35<=3,F35*SQRT(P35),0) -> 31373.366 | R35: =SQRT(P35/$AB$6) -> 9.3045151e+09 | S35: =2*$AB$6*R35 -> 0.087170328 | T35: =IF(G35<=3,F35*R35,0) -> 1.4495682e+10 | U35: =F35*P35 -> 6.3179666e+08 | V35: =H35^$AB$7*E35 -> 0.041372282 | W35: =I35^$AB$7*E35 -> 0.0010269239 | X35: =J35^$AB$7*E35 -> 0.00035340358 | Y35: =K35^$AB$7*E35 -> 0.00021534617
A36: 34 | B36: =C35 -> 7.9619944e-06 | C36: =(1/Inputs!$B$16)*(Inputs!$B$21/(1/Inputs!$B$16))^(33/60) -> 8.7150741e-06 | D36: =(B36+C36)/2 -> 8.3385342e-06 | E36: =C36-B36 -> 7.5307975e-07 | F36: =Inputs!$B$16*E36 -> 1.7052738 | G36: =IF(D36<=Inputs!$B$21,1,IF(D36<=Inputs!$B$22,2,IF(D36<=Inputs!$B$23,3,IF(D36<=Inputs!$B$24,4,5)))) -> 1 | H36: =Fit!$B$10*D36^(-1/Fit!$B$9) -> 56687.521 | I36: =EXP(Fit!$B$16+Fit!$B$15*-NORMSINV(D36)) -> 1468.3728 | J36: =Fit!$B$22*LN(1/D36)^(1/Fit!$B$21) -> 510.21405 | K36: =MAX(0,Fit!$B$28+Fit!$B$27*-NORMSINV(D36)) -> 311.75456 | L36: =INDEX(H36:K36,1,Inputs!$B$5) -> 56687.521 | M36: =L36*E36 -> 0.042690224 | N36: =L36^$AB$7 -> 56687.521 | O36: =N36*E36 -> 0.042690224 | P36: =N36*$AB$3/($AB$4*$AB$1) -> 3.8229813e+08 | Q36: =IF(G36<=3,F36*SQRT(P36),0) -> 33342.273 | R36: =SQRT(P36/$AB$6) -> 9.0339694e+09 | S36: =2*$AB$6*R36 -> 0.084635692 | T36: =IF(G36<=3,F36*R36,0) -> 1.5405391e+10 | U36: =F36*P36 -> 6.5192298e+08 | V36: =H36^$AB$7*E36 -> 0.042690224 | W36: =I36^$AB$7*E36 -> 0.0011058018 | X36: =J36^$AB$7*E36 -> 0.00038423187 | Y36: =K36^$AB$7*E36 -> 0.00023477604
A37: 35 | B37: =C36 -> 8.7150741e-06 | C37: =(1/Inputs!$B$16)*(Inputs!$B$21/(1/Inputs!$B$16))^(34/60) -> 9.5393834e-06 | D37: =(B37+C37)/2 -> 9.1272287e-06 | E37: =C37-B37 -> 8.2430928e-07 | F37: =Inputs!$B$16*E37 -> 1.8665659 | G37: =IF(D37<=Inputs!$B$21,1,IF(D37<=Inputs!$B$22,2,IF(D37<=Inputs!$B$23,3,IF(D37<=Inputs!$B$24,4,5)))) -> 1 | H37: =Fit!$B$10*D37^(-1/Fit!$B$9) -> 53438.863 | I37: =EXP(Fit!$B$16+Fit!$B$15*-NORMSINV(D37)) -> 1444.4281 | J37: =Fit!$B$22*LN(1/D37)^(1/Fit!$B$21) -> 506.7607 | K37: =MAX(0,Fit!$B$28+Fit!$B$27*-NORMSINV(D37)) -> 310.50305 | L37: =INDEX(H37:K37,1,Inputs!$B$5) -> 53438.863 | M37: =L37*E37 -> 0.044050151 | N37: =L37^$AB$7 -> 53438.863 | O37: =N37*E37 -> 0.044050151 | P37: =N37*$AB$3/($AB$4*$AB$1) -> 3.6038932e+08 | Q37: =IF(G37<=3,F37*SQRT(P37),0) -> 35434.743 | R37: =SQRT(P37/$AB$6) -> 8.7712903e+09 | S37: =2*$AB$6*R37 -> 0.082174755 | T37: =IF(G37<=3,F37*R37,0) -> 1.6372192e+10 | U37: =F37*P37 -> 6.7269043e+08 | V37: =H37^$AB$7*E37 -> 0.044050151 | W37: =I37^$AB$7*E37 -> 0.0011906555 | X37: =J37^$AB$7*E37 -> 0.00041772755 | Y37: =K37^$AB$7*E37 -> 0.00025595055
A38: 36 | B38: =C37 -> 9.5393834e-06 | C38: =(1/Inputs!$B$16)*(Inputs!$B$21/(1/Inputs!$B$16))^(35/60) -> 1.0441659e-05 | D38: =(B38+C38)/2 -> 9.9905214e-06 | E38: =C38-B38 -> 9.0227601e-07 | F38: =Inputs!$B$16*E38 -> 2.0431138 | G38: =IF(D38<=Inputs!$B$21,1,IF(D38<=Inputs!$B$22,2,IF(D38<=Inputs!$B$23,3,IF(D38<=Inputs!$B$24,4,5)))) -> 1 | H38: =Fit!$B$10*D38^(-1/Fit!$B$9) -> 50376.379 | I38: =EXP(Fit!$B$16+Fit!$B$15*-NORMSINV(D38)) -> 1420.7736 | J38: =Fit!$B$22*LN(1/D38)^(1/Fit!$B$21) -> 503.30401 | K38: =MAX(0,Fit!$B$28+Fit!$B$27*-NORMSINV(D38)) -> 309.24617 | L38: =INDEX(H38:K38,1,Inputs!$B$5) -> 50376.379 | M38: =L38*E38 -> 0.045453398 | N38: =L38^$AB$7 -> 50376.379 | O38: =N38*E38 -> 0.045453398 | P38: =N38*$AB$3/($AB$4*$AB$1) -> 3.3973606e+08 | Q38: =IF(G38<=3,F38*SQRT(P38),0) -> 37658.532 | R38: =SQRT(P38/$AB$6) -> 8.5162491e+09 | S38: =2*$AB$6*R38 -> 0.079785375 | T38: =IF(G38<=3,F38*R38,0) -> 1.7399666e+10 | U38: =F38*P38 -> 6.9411944e+08 | V38: =H38^$AB$7*E38 -> 0.045453398 | W38: =I38^$AB$7*E38 -> 0.0012819299 | X38: =J38^$AB$7*E38 -> 0.00045411913 | Y38: =K38^$AB$7*E38 -> 0.0002790254
A39: 37 | B39: =C38 -> 1.0441659e-05 | C39: =(1/Inputs!$B$16)*(Inputs!$B$21/(1/Inputs!$B$16))^(36/60) -> 1.1429277e-05 | D39: =(B39+C39)/2 -> 1.0935468e-05 | E39: =C39-B39 -> 9.8761716e-07 | F39: =Inputs!$B$16*E39 -> 2.2363603 | G39: =IF(D39<=Inputs!$B$21,1,IF(D39<=Inputs!$B$22,2,IF(D39<=Inputs!$B$23,3,IF(D39<=Inputs!$B$24,4,5)))) -> 1 | H39: =Fit!$B$10*D39^(-1/Fit!$B$9) -> 47489.401 | I39: =EXP(Fit!$B$16+Fit!$B$15*-NORMSINV(D39)) -> 1397.4067 | J39: =Fit!$B$22*LN(1/D39)^(1/Fit!$B$21) -> 499.84393 | K39: =MAX(0,Fit!$B$28+Fit!$B$27*-NORMSINV(D39)) -> 307.98387 | L39: =INDEX(H39:K39,1,Inputs!$B$5) -> 47489.401 | M39: =L39*E39 -> 0.046901347 | N39: =L39^$AB$7 -> 47489.401 | O39: =N39*E39 -> 0.046901347 | P39: =N39*$AB$3/($AB$4*$AB$1) -> 3.2026641e+08 | Q39: =IF(G39<=3,F39*SQRT(P39),0) -> 40021.879 | R39: =SQRT(P39/$AB$6) -> 8.2686237e+09 | S39: =2*$AB$6*R39 -> 0.07746547 | T39: =IF(G39<=3,F39*R39,0) -> 1.8491622e+10 | U39: =F39*P39 -> 7.1623109e+08 | V39: =H39^$AB$7*E39 -> 0.046901347 | W39: =I39^$AB$7*E39 -> 0.0013801029 | X39: =J39^$AB$7*E39 -> 0.00049365444 | Y39: =K39^$AB$7*E39 -> 0.00030417015
A40: 38 | B40: =C39 -> 1.1429277e-05 | C40: =(1/Inputs!$B$16)*(Inputs!$B$21/(1/Inputs!$B$16))^(37/60) -> 1.2510307e-05 | D40: =(B40+C40)/2 -> 1.1969792e-05 | E40: =C40-B40 -> 1.0810303e-06 | F40: =Inputs!$B$16*E40 -> 2.4478849 | G40: =IF(D40<=Inputs!$B$21,1,IF(D40<=Inputs!$B$22,2,IF(D40<=Inputs!$B$23,3,IF(D40<=Inputs!$B$24,4,5)))) -> 1 | H40: =Fit!$B$10*D40^(-1/Fit!$B$9) -> 44767.87 | I40: =EXP(Fit!$B$16+Fit!$B$15*-NORMSINV(D40)) -> 1374.3248 | J40: =Fit!$B$22*LN(1/D40)^(1/Fit!$B$21) -> 496.38043 | K40: =MAX(0,Fit!$B$28+Fit!$B$27*-NORMSINV(D40)) -> 306.71605 | L40: =INDEX(H40:K40,1,Inputs!$B$5) -> 44767.87 | M40: =L40*E40 -> 0.048395422 | N40: =L40^$AB$7 -> 44767.87 | O40: =N40*E40 -> 0.048395422 | P40: =N40*$AB$3/($AB$4*$AB$1) -> 3.0191253e+08 | Q40: =IF(G40<=3,F40*SQRT(P40),0) -> 42533.543 | R40: =SQRT(P40/$AB$6) -> 8.0281984e+09 | S40: =2*$AB$6*R40 -> 0.075213021 | T40: =IF(G40<=3,F40*R40,0) -> 1.9652106e+10 | U40: =F40*P40 -> 7.3904712e+08 | V40: =H40^$AB$7*E40 -> 0.048395422 | W40: =I40^$AB$7*E40 -> 0.0014856866 | X40: =J40^$AB$7*E40 -> 0.00053660226 | Y40: =K40^$AB$7*E40 -> 0.00033156933
...

Sheet Notes
A1: Method, sources and limitations
A3: THE MODEL
A4: Berk, J.B. and van Binsbergen, J.H. (2015), "Measuring Skill in the Mutual Fund Industry", Journal of Financial Economics 118(1), Section 4, equations 14-16.
A5: Alpha declines linearly with the size of the book: alpha(A) = S - b*A. Dollar value added is V = A*(S - b*A).
A6: Maximising over A gives the optimal book A* = S/(2b) and the value at that book V* = S^2/(4b). Two identities follow and are used here: the alpha earned at the optimum is S/2, and A* = SQRT(V*/b).
A8: STEP BY STEP
A9: 1. Fit the chosen distribution to two upper-tail quantiles (Inputs B9:B12). Every distribution has a closed form for this, shown on the Fit sheet.
A10: 2. Decide whether the fitted shape describes value added V or skill S (Inputs B6). If S, then V is proportional to S^2, which for a Pareto halves the effective exponent. An effective exponent below 1 has no finite mean and the result is dominated by the single top person.
A11: 3. Build a grid of population bands in quantile space. Row 3 of the Grid sheet is rank 1 on its own, occupying u from 0 to 1/N and evaluated at the plotting position (Inputs B17). The rest is 60 log-spaced bands within each tier, so band edges land exactly on the tier boundaries.
A12: 4. For each band compute the quantile x(u_mid), the weight w = x^power, and the contribution w*du. The sum of contributions, T, normalises the shares.
A13: 5. Value per person at quantile u is V = w * Pool / (N * T). By construction the population total equals the pool exactly.
A14: 6. Restrict the book-running population to the top 1%. Solve b from the requirement that their optimal books sum to the capital input: b = (SUM over the top 1% of people*SQRT(V) / Capital)^2.
... A43: Blue text on yellow fill: input cells, safe to edit. Black: formulas. Grey fill: read-only.
