Workbook

Sheet README
A1: Graduate-recruitment ecosystem — graph dataset
A2: Source file | B2: graduate programs.md — 'Financial-Services Graduate/Campus Recruitment Target Lists — Five Regions'
A3: Purpose | B3: Node/edge tables ready to re-render as a network graph (geographic + organisational links, organisation size, yearly graduate intake).
A5: SHEETS
A6: Nodes | B6: One row per graph node. node_id is the primary key referenced by the Edges sheet.
A7: Edges | B7: One row per relationship. source_id and target_id both reference Nodes[node_id].
A8: Vocabulary | B8: Controlled value lists for node_type, edge_type, org_size_band, confirmation_status, data_confidence, geo_source.
A9: Summary | B9: Counts and coverage diagnostics, all formula-driven off Nodes and Edges.
A11: HOW TO RENDER
A12: Geography | B12: Hub → Country → Region form a PART_OF tree. Organisations attach to hubs via LOCATED_IN. A multinational has MULTIPLE LOCATED_IN edges, which is how cross-region presence is expressed (e.g. ORG_JPM sits in New York, Bengaluru, Hyderabad, Mumbai, São Paulo, Dublin and Luxembourg).
A13: Organisational links | B13: PARENT_OF (group → subsidiary), ABSORBED_BY (Credit Suisse → UBS), COMPETES_FOR_TALENT (undirected), IN_SECTOR (organisation → sector).
A14: Recruitment channel | B14: RECRUITS_VIA (organisation → Mechanism node) carries the entry mechanism; the Mechanism node holds cycle_timing and lead_time_months. RECRUITS_FROM / PARTNERS_WITH / RECRUITS_VIA_INTERMEDIARY point at TalentPool nodes.
A15: Node size | B15: Use annual_intake_low / annual_intake_high where populated; otherwise fall back to org_size_band (ordinal: Boutique < Mid < Large < Mega).
A16: Edge direction | B16: The 'directed' column is TRUE for all edge types except COMPETES_FOR_TALENT.
A18: DATA-QUALITY WARNINGS — READ BEFORE WEIGHTING NODES
A19: 1. Intake is almost entirely absent from the source. | B19: annual_intake_low / high / applications_per_cycle are populated for only 5 organisations (SBI, Evercore, Citadel Securities, ECB, Credit Suisse). Every other cell is deliberately blank — blank means UNKNOWN, not zero. Do not treat a blank as a small cohort.
A20: 2. org_size_band is INFERRED, not sourced. | B20: The source document contains no headcount or balance-sheet data. Bands are a coarse editorial judgement and every organisation row says so in size_basis. Replace them before using size quantitatively.
A21: 3. Confirmation status is a research artefact. | B21: [Note] means no formal scheme was confirmed in the research pass — NOT that no programme exists. The source flags China, LatAm and European insurers as especially under-verified.
A22: 4. Cohort/selectivity figures are secondary-sourced. | B22: US boutique and quant figures derive from career-advice sites and forums, not firm disclosures. Treat as indicative.
A23: 5. Grouped rows exist. | B23: A few nodes bundle several firms as the source did (ORG_BIG4, ORG_MBB, ORG_IN_LIFEINS, ORG_IN_AMC, ORG_LATAM_BIG4, ORG_LATAM_MBB). Split them if per-firm resolution matters.
A24: 6. Hub geography is partly inferred. | B24: geo_source = 'source' where the document names the city, 'inferred' where a well-known head-office location was used to place the node.
A25: 7. UK is out of scope. | B25: GEO_R_OTHER / GEO_C_UK / GEO_H_LON exist only so HSBC, Barclays and Standard Chartered resolve to a home base; the source covers five regions and excludes the UK.
A27: ENRICHMENT ORDER (from the source's own recommendations)
A28: Stage 1 | B28: Seed the graph with [C-Official] organisations only for a defensible core.
A29: Stage 2 | B29: Weight inflow by mechanism and scale, not firm size: mass channels (SBI/IBPS exams, Chinese Big Four quotas) are high-volume; boutiques and quant firms are low-volume/high-selectivity. Keep cohort size and selectivity as separate attributes.
A30: Stage 3 | B30: Treat the mechanism as an edge property with a lead-time parameter (already on the Mechanism nodes).
A31: Stage 4 | B31: Verify the [Note] tail on Chinese-language and Spanish/Portuguese careers pages before assigning any inflow weight.
A33: REGION 6 — UNITED KINGDOM (added by research, not in the source file)
A34: Why it exists | B34: The source document treats the UK list as its structural template and excludes it from the five regions it covers. The UK was originally a three-organisation placeholder (GEO_R_OTHER) so that HSBC, Barclays and Standard Chartered had a home base. It is now a full region, GEO_R_UK.
A35: Provenance | B35: Every UK organisation row carries geo_source = 'research'. Programme detail confirmed on a first-party careers site is marked [C-Official] and the exact URL is attached as a cell note on the programme_name, program_length_months and notes cells. Everything else is [Note] — a plausible UK graduate recruiter whose scheme was not verified in this pass.
A36: Confirmed to first-party sources | B36: Bank of England (Graduate Development Programme, 24 months to a permanent role, GBP 33,525, 2026 round opened for Leeds only), FCA (two-year rotational scheme with an external secondment, ~10 programme areas), Lloyds Banking Group (schemes across Data Science, Technology Engineering, Finance, Risk, Commercial Banking, Consumer Banking, Actuarial), NatWest Group (Engineering, Finance, Digital Transformation, NatWest Markets), Lloyd's of London (six two-year programmes, four six-month placements).
A37: Two UK mechanisms | B37: MECH_UK_SPRING is the Spring Week to summer internship to graduate scheme funnel the source contrasts the US against; its lead_time_months of 30 is the longest in the dataset. MECH_UK_SCHEME is direct autumn-to-September entry, used by retail banks, insurers, regulators and professional-services firms.
A38: London as a hub | B38: GEO_H_LON now carries 87 LOCATED_IN edges — every global bank, quant firm, custodian and data vendor already in the dataset that runs a London graduate intake, plus the UK-domiciled institutions. It is the densest node in the graph and will dominate any force-directed layout; consider collapsing it or weighting it down when rendering.
A39: Beware the name collision | B39: ORG_UK_LLOYDSBG (Lloyds Banking Group, a retail bank) and ORG_UK_LLOYDSMKT (Lloyd's of London, a specialist insurance market) are unrelated institutions.
A40: Intake is still unknown | B40: No UK organisation has a published cohort size in this pass, so annual_intake_low/high remain blank for all of them. The Bank of England salary figure is the only hard number the research produced.
A41: Grouped UK rows | B41: ORG_UK_BIG4, ORG_UK_MBB and ORG_UK_MIDTIER each bundle several firms, matching how the source groups them.
A43: INTAKE ESTIMATE (columns S and T on Nodes)
A44: Why it exists | B44: The source document supplies a cohort size for only five organisations, which makes the graph impossible to size by intake. Column S gives every organisation a central estimate so nodes can be scaled; column T records how each figure was arrived at.
A45: It is a formula, not typed numbers | B45: Every cell in S is a formula. Documented rows take the midpoint of annual_intake_low/high. Everything else is size-band base x sector factor x mechanism factor, with all three grids on the Assumptions sheet. Change a factor there and the whole column plus the Summary totals recalculate.
A46: Confidence | B46: 5 of 246 figures are sourced. The other 241 are order-of-magnitude judgements by Claude and carry no external authority. Use them to size nodes; do not quote them as intake statistics or aggregate them into a headline number you would defend.
...

Sheet Nodes
A1: node_id | B1: label | C1: node_type | D1: region | E1: country | F1: hub_city | G1: sector | H1: subsector_tier | I1: entry_mechanism_id | J1: program_name | K1: program_length_months | L1: cycle_timing | M1: lead_time_months | N1: org_size_band | O1: size_basis | P1: annual_intake_low | Q1: annual_intake_high | R1: applications_per_cycle | S1: intake_estimate_central | T1: intake_estimate_basis | U1: confirmation_status | V1: data_confidence | W1: geo_source | X1: notes
A2: GEO_R_USA | B2: USA | C2: Region | D2: USA | S2: =IF($C2<>"Organisation","",IF(OR($P2<>"",$Q2<>""),IF($P2<>"",IF($Q2<>"",($P2+$Q2)/2,$P2),$Q2),ROUND(_xlfn.XLOOKUP($N2,Assumptions!$B$5:$B$9,Assumptions!$C$5:$C$9,0)*_xlfn.XLOOKUP($G2,Assumptions!$B$13:$B$26,Assumptions!$C$13:$C$26,0)*_xlfn.XLOOKUP($I2,Assumptions!$B$30:$B$50,Assumptions!$C$30:$C$50,0),0))) | T2: =IF($C2<>"Organisation","",IF(OR($P2<>"",$Q2<>""),"Documented in source - midpoint of annual_intake_low/high",IF($I2="","No confirmed programme - modelled as zero",$N2&" base x "&TEXT(_xlfn.XLOOKUP($G2,Assumptions!$B$13:$B$26,Assumptions!$C$13:$C$26,0),"0.0#")&" sector x "&TEXT(_xlfn.XLOOKUP($I2,Assumptions!$B$30:$B$50,Assumptions!$C$30:$C$50,0),"0.0#")&" mechanism"))) | X2: Source region
A3: GEO_R_INDIA | B3: India | C3: Region | D3: India | S3: =IF($C3<>"Organisation","",IF(OR($P3<>"",$Q3<>""),IF($P3<>"",IF($Q3<>"",($P3+$Q3)/2,$P3),$Q3),ROUND(_xlfn.XLOOKUP($N3,Assumptions!$B$5:$B$9,Assumptions!$C$5:$C$9,0)*_xlfn.XLOOKUP($G3,Assumptions!$B$13:$B$26,Assumptions!$C$13:$C$26,0)*_xlfn.XLOOKUP($I3,Assumptions!$B$30:$B$50,Assumptions!$C$30:$C$50,0),0))) | T3: =IF($C3<>"Organisation","",IF(OR($P3<>"",$Q3<>""),"Documented in source - midpoint of annual_intake_low/high",IF($I3="","No confirmed programme - modelled as zero",$N3&" base x "&TEXT(_xlfn.XLOOKUP($G3,Assumptions!$B$13:$B$26,Assumptions!$C$13:$C$26,0),"0.0#")&" sector x "&TEXT(_xlfn.XLOOKUP($I3,Assumptions!$B$30:$B$50,Assumptions!$C$30:$C$50,0),"0.0#")&" mechanism"))) | X3: Source region
A4: GEO_R_CHINA | B4: China | C4: Region | D4: China | S4: =IF($C4<>"Organisation","",IF(OR($P4<>"",$Q4<>""),IF($P4<>"",IF($Q4<>"",($P4+$Q4)/2,$P4),$Q4),ROUND(_xlfn.XLOOKUP($N4,Assumptions!$B$5:$B$9,Assumptions!$C$5:$C$9,0)*_xlfn.XLOOKUP($G4,Assumptions!$B$13:$B$26,Assumptions!$C$13:$C$26,0)*_xlfn.XLOOKUP($I4,Assumptions!$B$30:$B$50,Assumptions!$C$30:$C$50,0),0))) | T4: =IF($C4<>"Organisation","",IF(OR($P4<>"",$Q4<>""),"Documented in source - midpoint of annual_intake_low/high",IF($I4="","No confirmed programme - modelled as zero",$N4&" base x "&TEXT(_xlfn.XLOOKUP($G4,Assumptions!$B$13:$B$26,Assumptions!$C$13:$C$26,0),"0.0#")&" sector x "&TEXT(_xlfn.XLOOKUP($I4,Assumptions!$B$30:$B$50,Assumptions!$C$30:$C$50,0),"0.0#")&" mechanism"))) | X4: Source region
A5: GEO_R_LATAM | B5: Latin America | C5: Region | D5: Latin America | S5: =IF($C5<>"Organisation","",IF(OR($P5<>"",$Q5<>""),IF($P5<>"",IF($Q5<>"",($P5+$Q5)/2,$P5),$Q5),ROUND(_xlfn.XLOOKUP($N5,Assumptions!$B$5:$B$9,Assumptions!$C$5:$C$9,0)*_xlfn.XLOOKUP($G5,Assumptions!$B$13:$B$26,Assumptions!$C$13:$C$26,0)*_xlfn.XLOOKUP($I5,Assumptions!$B$30:$B$50,Assumptions!$C$30:$C$50,0),0))) | T5: =IF($C5<>"Organisation","",IF(OR($P5<>"",$Q5<>""),"Documented in source - midpoint of annual_intake_low/high",IF($I5="","No confirmed programme - modelled as zero",$N5&" base x "&TEXT(_xlfn.XLOOKUP($G5,Assumptions!$B$13:$B$26,Assumptions!$C$13:$C$26,0),"0.0#")&" sector x "&TEXT(_xlfn.XLOOKUP($I5,Assumptions!$B$30:$B$50,Assumptions!$C$30:$C$50,0),"0.0#")&" mechanism"))) | X5: Source region
A6: GEO_R_EUROPE | B6: Continental Europe | C6: Region | D6: Continental Europe | S6: =IF($C6<>"Organisation","",IF(OR($P6<>"",$Q6<>""),IF($P6<>"",IF($Q6<>"",($P6+$Q6)/2,$P6),$Q6),ROUND(_xlfn.XLOOKUP($N6,Assumptions!$B$5:$B$9,Assumptions!$C$5:$C$9,0)*_xlfn.XLOOKUP($G6,Assumptions!$B$13:$B$26,Assumptions!$C$13:$C$26,0)*_xlfn.XLOOKUP($I6,Assumptions!$B$30:$B$50,Assumptions!$C$30:$C$50,0),0))) | T6: =IF($C6<>"Organisation","",IF(OR($P6<>"",$Q6<>""),"Documented in source - midpoint of annual_intake_low/high",IF($I6="","No confirmed programme - modelled as zero",$N6&" base x "&TEXT(_xlfn.XLOOKUP($G6,Assumptions!$B$13:$B$26,Assumptions!$C$13:$C$26,0),"0.0#")&" sector x "&TEXT(_xlfn.XLOOKUP($I6,Assumptions!$B$30:$B$50,Assumptions!$C$30:$C$50,0),"0.0#")&" mechanism"))) | X6: Source region
A7: GEO_R_UK | B7: United Kingdom | C7: Region | D7: United Kingdom | S7: =IF($C7<>"Organisation","",IF(OR($P7<>"",$Q7<>""),IF($P7<>"",IF($Q7<>"",($P7+$Q7)/2,$P7),$Q7),ROUND(_xlfn.XLOOKUP($N7,Assumptions!$B$5:$B$9,Assumptions!$C$5:$C$9,0)*_xlfn.XLOOKUP($G7,Assumptions!$B$13:$B$26,Assumptions!$C$13:$C$26,0)*_xlfn.XLOOKUP($I7,Assumptions!$B$30:$B$50,Assumptions!$C$30:$C$50,0),0))) | T7: =IF($C7<>"Organisation","",IF(OR($P7<>"",$Q7<>""),"Documented in source - midpoint of annual_intake_low/high",IF($I7="","No confirmed programme - modelled as zero",$N7&" base x "&TEXT(_xlfn.XLOOKUP($G7,Assumptions!$B$13:$B$26,Assumptions!$C$13:$C$26,0),"0.0#")&" sector x "&TEXT(_xlfn.XLOOKUP($I7,Assumptions!$B$30:$B$50,Assumptions!$C$30:$C$50,0),"0.0#")&" mechanism"))) | X7: Source region 6 - added by research, not present in the source document (the source covers five regions and treats the UK list as its structural template only)
A8: GEO_C_US | B8: United States | C8: Country | D8: USA | E8: United States | S8: =IF($C8<>"Organisation","",IF(OR($P8<>"",$Q8<>""),IF($P8<>"",IF($Q8<>"",($P8+$Q8)/2,$P8),$Q8),ROUND(_xlfn.XLOOKUP($N8,Assumptions!$B$5:$B$9,Assumptions!$C$5:$C$9,0)*_xlfn.XLOOKUP($G8,Assumptions!$B$13:$B$26,Assumptions!$C$13:$C$26,0)*_xlfn.XLOOKUP($I8,Assumptions!$B$30:$B$50,Assumptions!$C$30:$C$50,0),0))) | T8: =IF($C8<>"Organisation","",IF(OR($P8<>"",$Q8<>""),"Documented in source - midpoint of annual_intake_low/high",IF($I8="","No confirmed programme - modelled as zero",$N8&" base x "&TEXT(_xlfn.XLOOKUP($G8,Assumptions!$B$13:$B$26,Assumptions!$C$13:$C$26,0),"0.0#")&" sector x "&TEXT(_xlfn.XLOOKUP($I8,Assumptions!$B$30:$B$50,Assumptions!$C$30:$C$50,0),"0.0#")&" mechanism")))
A9: GEO_C_IN | B9: India | C9: Country | D9: India | E9: India | S9: =IF($C9<>"Organisation","",IF(OR($P9<>"",$Q9<>""),IF($P9<>"",IF($Q9<>"",($P9+$Q9)/2,$P9),$Q9),ROUND(_xlfn.XLOOKUP($N9,Assumptions!$B$5:$B$9,Assumptions!$C$5:$C$9,0)*_xlfn.XLOOKUP($G9,Assumptions!$B$13:$B$26,Assumptions!$C$13:$C$26,0)*_xlfn.XLOOKUP($I9,Assumptions!$B$30:$B$50,Assumptions!$C$30:$C$50,0),0))) | T9: =IF($C9<>"Organisation","",IF(OR($P9<>"",$Q9<>""),"Documented in source - midpoint of annual_intake_low/high",IF($I9="","No confirmed programme - modelled as zero",$N9&" base x "&TEXT(_xlfn.XLOOKUP($G9,Assumptions!$B$13:$B$26,Assumptions!$C$13:$C$26,0),"0.0#")&" sector x "&TEXT(_xlfn.XLOOKUP($I9,Assumptions!$B$30:$B$50,Assumptions!$C$30:$C$50,0),"0.0#")&" mechanism")))
A10: GEO_C_CN | B10: China | C10: Country | D10: China | E10: China | S10: =IF($C10<>"Organisation","",IF(OR($P10<>"",$Q10<>""),IF($P10<>"",IF($Q10<>"",($P10+$Q10)/2,$P10),$Q10),ROUND(_xlfn.XLOOKUP($N10,Assumptions!$B$5:$B$9,Assumptions!$C$5:$C$9,0)*_xlfn.XLOOKUP($G10,Assumptions!$B$13:$B$26,Assumptions!$C$13:$C$26,0)*_xlfn.XLOOKUP($I10,Assumptions!$B$30:$B$50,Assumptions!$C$30:$C$50,0),0))) | T10: =IF($C10<>"Organisation","",IF(OR($P10<>"",$Q10<>""),"Documented in source - midpoint of annual_intake_low/high",IF($I10="","No confirmed programme - modelled as zero",$N10&" base x "&TEXT(_xlfn.XLOOKUP($G10,Assumptions!$B$13:$B$26,Assumptions!$C$13:$C$26,0),"0.0#")&" sector x "&TEXT(_xlfn.XLOOKUP($I10,Assumptions!$B$30:$B$50,Assumptions!$C$30:$C$50,0),"0.0#")&" mechanism")))
A11: GEO_C_BR | B11: Brazil | C11: Country | D11: Latin America | E11: Brazil | S11: =IF($C11<>"Organisation","",IF(OR($P11<>"",$Q11<>""),IF($P11<>"",IF($Q11<>"",($P11+$Q11)/2,$P11),$Q11),ROUND(_xlfn.XLOOKUP($N11,Assumptions!$B$5:$B$9,Assumptions!$C$5:$C$9,0)*_xlfn.XLOOKUP($G11,Assumptions!$B$13:$B$26,Assumptions!$C$13:$C$26,0)*_xlfn.XLOOKUP($I11,Assumptions!$B$30:$B$50,Assumptions!$C$30:$C$50,0),0))) | T11: =IF($C11<>"Organisation","",IF(OR($P11<>"",$Q11<>""),"Documented in source - midpoint of annual_intake_low/high",IF($I11="","No confirmed programme - modelled as zero",$N11&" base x "&TEXT(_xlfn.XLOOKUP($G11,Assumptions!$B$13:$B$26,Assumptions!$C$13:$C$26,0),"0.0#")&" sector x "&TEXT(_xlfn.XLOOKUP($I11,Assumptions!$B$30:$B$50,Assumptions!$C$30:$C$50,0),"0.0#")&" mechanism")))
A12: GEO_C_MX | B12: Mexico | C12: Country | D12: Latin America | E12: Mexico | S12: =IF($C12<>"Organisation","",IF(OR($P12<>"",$Q12<>""),IF($P12<>"",IF($Q12<>"",($P12+$Q12)/2,$P12),$Q12),ROUND(_xlfn.XLOOKUP($N12,Assumptions!$B$5:$B$9,Assumptions!$C$5:$C$9,0)*_xlfn.XLOOKUP($G12,Assumptions!$B$13:$B$26,Assumptions!$C$13:$C$26,0)*_xlfn.XLOOKUP($I12,Assumptions!$B$30:$B$50,Assumptions!$C$30:$C$50,0),0))) | T12: =IF($C12<>"Organisation","",IF(OR($P12<>"",$Q12<>""),"Documented in source - midpoint of annual_intake_low/high",IF($I12="","No confirmed programme - modelled as zero",$N12&" base x "&TEXT(_xlfn.XLOOKUP($G12,Assumptions!$B$13:$B$26,Assumptions!$C$13:$C$26,0),"0.0#")&" sector x "&TEXT(_xlfn.XLOOKUP($I12,Assumptions!$B$30:$B$50,Assumptions!$C$30:$C$50,0),"0.0#")&" mechanism")))
A13: GEO_C_CO | B13: Colombia | C13: Country | D13: Latin America | E13: Colombia | S13: =IF($C13<>"Organisation","",IF(OR($P13<>"",$Q13<>""),IF($P13<>"",IF($Q13<>"",($P13+$Q13)/2,$P13),$Q13),ROUND(_xlfn.XLOOKUP($N13,Assumptions!$B$5:$B$9,Assumptions!$C$5:$C$9,0)*_xlfn.XLOOKUP($G13,Assumptions!$B$13:$B$26,Assumptions!$C$13:$C$26,0)*_xlfn.XLOOKUP($I13,Assumptions!$B$30:$B$50,Assumptions!$C$30:$C$50,0),0))) | T13: =IF($C13<>"Organisation","",IF(OR($P13<>"",$Q13<>""),"Documented in source - midpoint of annual_intake_low/high",IF($I13="","No confirmed programme - modelled as zero",$N13&" base x "&TEXT(_xlfn.XLOOKUP($G13,Assumptions!$B$13:$B$26,Assumptions!$C$13:$C$26,0),"0.0#")&" sector x "&TEXT(_xlfn.XLOOKUP($I13,Assumptions!$B$30:$B$50,Assumptions!$C$30:$C$50,0),"0.0#")&" mechanism")))
A14: GEO_C_CL | B14: Chile | C14: Country | D14: Latin America | E14: Chile | S14: =IF($C14<>"Organisation","",IF(OR($P14<>"",$Q14<>""),IF($P14<>"",IF($Q14<>"",($P14+$Q14)/2,$P14),$Q14),ROUND(_xlfn.XLOOKUP($N14,Assumptions!$B$5:$B$9,Assumptions!$C$5:$C$9,0)*_xlfn.XLOOKUP($G14,Assumptions!$B$13:$B$26,Assumptions!$C$13:$C$26,0)*_xlfn.XLOOKUP($I14,Assumptions!$B$30:$B$50,Assumptions!$C$30:$C$50,0),0))) | T14: =IF($C14<>"Organisation","",IF(OR($P14<>"",$Q14<>""),"Documented in source - midpoint of annual_intake_low/high",IF($I14="","No confirmed programme - modelled as zero",$N14&" base x "&TEXT(_xlfn.XLOOKUP($G14,Assumptions!$B$13:$B$26,Assumptions!$C$13:$C$26,0),"0.0#")&" sector x "&TEXT(_xlfn.XLOOKUP($I14,Assumptions!$B$30:$B$50,Assumptions!$C$30:$C$50,0),"0.0#")&" mechanism")))
A15: GEO_C_PE | B15: Peru | C15: Country | D15: Latin America | E15: Peru | S15: =IF($C15<>"Organisation","",IF(OR($P15<>"",$Q15<>""),IF($P15<>"",IF($Q15<>"",($P15+$Q15)/2,$P15),$Q15),ROUND(_xlfn.XLOOKUP($N15,Assumptions!$B$5:$B$9,Assumptions!$C$5:$C$9,0)*_xlfn.XLOOKUP($G15,Assumptions!$B$13:$B$26,Assumptions!$C$13:$C$26,0)*_xlfn.XLOOKUP($I15,Assumptions!$B$30:$B$50,Assumptions!$C$30:$C$50,0),0))) | T15: =IF($C15<>"Organisation","",IF(OR($P15<>"",$Q15<>""),"Documented in source - midpoint of annual_intake_low/high",IF($I15="","No confirmed programme - modelled as zero",$N15&" base x "&TEXT(_xlfn.XLOOKUP($G15,Assumptions!$B$13:$B$26,Assumptions!$C$13:$C$26,0),"0.0#")&" sector x "&TEXT(_xlfn.XLOOKUP($I15,Assumptions!$B$30:$B$50,Assumptions!$C$30:$C$50,0),"0.0#")&" mechanism")))
A16: GEO_C_AR | B16: Argentina | C16: Country | D16: Latin America | E16: Argentina | S16: =IF($C16<>"Organisation","",IF(OR($P16<>"",$Q16<>""),IF($P16<>"",IF($Q16<>"",($P16+$Q16)/2,$P16),$Q16),ROUND(_xlfn.XLOOKUP($N16,Assumptions!$B$5:$B$9,Assumptions!$C$5:$C$9,0)*_xlfn.XLOOKUP($G16,Assumptions!$B$13:$B$26,Assumptions!$C$13:$C$26,0)*_xlfn.XLOOKUP($I16,Assumptions!$B$30:$B$50,Assumptions!$C$30:$C$50,0),0))) | T16: =IF($C16<>"Organisation","",IF(OR($P16<>"",$Q16<>""),"Documented in source - midpoint of annual_intake_low/high",IF($I16="","No confirmed programme - modelled as zero",$N16&" base x "&TEXT(_xlfn.XLOOKUP($G16,Assumptions!$B$13:$B$26,Assumptions!$C$13:$C$26,0),"0.0#")&" sector x "&TEXT(_xlfn.XLOOKUP($I16,Assumptions!$B$30:$B$50,Assumptions!$C$30:$C$50,0),"0.0#")&" mechanism")))
A17: GEO_C_DE | B17: Germany | C17: Country | D17: Continental Europe | E17: Germany | S17: =IF($C17<>"Organisation","",IF(OR($P17<>"",$Q17<>""),IF($P17<>"",IF($Q17<>"",($P17+$Q17)/2,$P17),$Q17),ROUND(_xlfn.XLOOKUP($N17,Assumptions!$B$5:$B$9,Assumptions!$C$5:$C$9,0)*_xlfn.XLOOKUP($G17,Assumptions!$B$13:$B$26,Assumptions!$C$13:$C$26,0)*_xlfn.XLOOKUP($I17,Assumptions!$B$30:$B$50,Assumptions!$C$30:$C$50,0),0))) | T17: =IF($C17<>"Organisation","",IF(OR($P17<>"",$Q17<>""),"Documented in source - midpoint of annual_intake_low/high",IF($I17="","No confirmed programme - modelled as zero",$N17&" base x "&TEXT(_xlfn.XLOOKUP($G17,Assumptions!$B$13:$B$26,Assumptions!$C$13:$C$26,0),"0.0#")&" sector x "&TEXT(_xlfn.XLOOKUP($I17,Assumptions!$B$30:$B$50,Assumptions!$C$30:$C$50,0),"0.0#")&" mechanism")))
A18: GEO_C_FR | B18: France | C18: Country | D18: Continental Europe | E18: France | S18: =IF($C18<>"Organisation","",IF(OR($P18<>"",$Q18<>""),IF($P18<>"",IF($Q18<>"",($P18+$Q18)/2,$P18),$Q18),ROUND(_xlfn.XLOOKUP($N18,Assumptions!$B$5:$B$9,Assumptions!$C$5:$C$9,0)*_xlfn.XLOOKUP($G18,Assumptions!$B$13:$B$26,Assumptions!$C$13:$C$26,0)*_xlfn.XLOOKUP($I18,Assumptions!$B$30:$B$50,Assumptions!$C$30:$C$50,0),0))) | T18: =IF($C18<>"Organisation","",IF(OR($P18<>"",$Q18<>""),"Documented in source - midpoint of annual_intake_low/high",IF($I18="","No confirmed programme - modelled as zero",$N18&" base x "&TEXT(_xlfn.XLOOKUP($G18,Assumptions!$B$13:$B$26,Assumptions!$C$13:$C$26,0),"0.0#")&" sector x "&TEXT(_xlfn.XLOOKUP($I18,Assumptions!$B$30:$B$50,Assumptions!$C$30:$C$50,0),"0.0#")&" mechanism")))
A19: GEO_C_CH | B19: Switzerland | C19: Country | D19: Continental Europe | E19: Switzerland | S19: =IF($C19<>"Organisation","",IF(OR($P19<>"",$Q19<>""),IF($P19<>"",IF($Q19<>"",($P19+$Q19)/2,$P19),$Q19),ROUND(_xlfn.XLOOKUP($N19,Assumptions!$B$5:$B$9,Assumptions!$C$5:$C$9,0)*_xlfn.XLOOKUP($G19,Assumptions!$B$13:$B$26,Assumptions!$C$13:$C$26,0)*_xlfn.XLOOKUP($I19,Assumptions!$B$30:$B$50,Assumptions!$C$30:$C$50,0),0))) | T19: =IF($C19<>"Organisation","",IF(OR($P19<>"",$Q19<>""),"Documented in source - midpoint of annual_intake_low/high",IF($I19="","No confirmed programme - modelled as zero",$N19&" base x "&TEXT(_xlfn.XLOOKUP($G19,Assumptions!$B$13:$B$26,Assumptions!$C$13:$C$26,0),"0.0#")&" sector x "&TEXT(_xlfn.XLOOKUP($I19,Assumptions!$B$30:$B$50,Assumptions!$C$30:$C$50,0),"0.0#")&" mechanism")))
... A28: GEO_C_LU | B28: Luxembourg | C28: Country | D28: Continental Europe | E28: Luxembourg | S28: =IF($C28<>"Organisation","",IF(OR($P28<>"",$Q28<>""),IF($P28<>"",IF($Q28<>"",($P28+$Q28)/2,$P28),$Q28),ROUND(_xlfn.XLOOKUP($N28,Assumptions!$B$5:$B$9,Assumptions!$C$5:$C$9,0)*_xlfn.XLOOKUP($G28,Assumptions!$B$13:$B$26,Assumptions!$C$13:$C$26,0)*_xlfn.XLOOKUP($I28,Assumptions!$B$30:$B$50,Assumptions!$C$30:$C$50,0),0))) | T28: =IF($C28<>"Organisation","",IF(OR($P28<>"",$Q28<>""),"Documented in source - midpoint of annual_intake_low/high",IF($I28="","No confirmed programme - modelled as zero",$N28&" base x "&TEXT(_xlfn.XLOOKUP($G28,Assumptions!$B$13:$B$26,Assumptions!$C$13:$C$26,0),"0.0#")&" sector x "&TEXT(_xlfn.XLOOKUP($I28,Assumptions!$B$30:$B$50,Assumptions!$C$30:$C$50,0),"0.0#")&" mechanism")))
A29: GEO_C_UK | B29: United Kingdom | C29: Country | D29: United Kingdom | E29: United Kingdom | S29: =IF($C29<>"Organisation","",IF(OR($P29<>"",$Q29<>""),IF($P29<>"",IF($Q29<>"",($P29+$Q29)/2,$P29),$Q29),ROUND(_xlfn.XLOOKUP($N29,Assumptions!$B$5:$B$9,Assumptions!$C$5:$C$9,0)*_xlfn.XLOOKUP($G29,Assumptions!$B$13:$B$26,Assumptions!$C$13:$C$26,0)*_xlfn.XLOOKUP($I29,Assumptions!$B$30:$B$50,Assumptions!$C$30:$C$50,0),0))) | T29: =IF($C29<>"Organisation","",IF(OR($P29<>"",$Q29<>""),"Documented in source - midpoint of annual_intake_low/high",IF($I29="","No confirmed programme - modelled as zero",$N29&" base x "&TEXT(_xlfn.XLOOKUP($G29,Assumptions!$B$13:$B$26,Assumptions!$C$13:$C$26,0),"0.0#")&" sector x "&TEXT(_xlfn.XLOOKUP($I29,Assumptions!$B$30:$B$50,Assumptions!$C$30:$C$50,0),"0.0#")&" mechanism"))) | X29: Promoted from out-of-scope placeholder to a full region
A30: GEO_H_NYC | B30: New York | C30: Hub | D30: USA | E30: United States | F30: New York | S30: =IF($C30<>"Organisation","",IF(OR($P30<>"",$Q30<>""),IF($P30<>"",IF($Q30<>"",($P30+$Q30)/2,$P30),$Q30),ROUND(_xlfn.XLOOKUP($N30,Assumptions!$B$5:$B$9,Assumptions!$C$5:$C$9,0)*_xlfn.XLOOKUP($G30,Assumptions!$B$13:$B$26,Assumptions!$C$13:$C$26,0)*_xlfn.XLOOKUP($I30,Assumptions!$B$30:$B$50,Assumptions!$C$30:$C$50,0),0))) | T30: =IF($C30<>"Organisation","",IF(OR($P30<>"",$Q30<>""),"Documented in source - midpoint of annual_intake_low/high",IF($I30="","No confirmed programme - modelled as zero",$N30&" base x "&TEXT(_xlfn.XLOOKUP($G30,Assumptions!$B$13:$B$26,Assumptions!$C$13:$C$26,0),"0.0#")&" sector x "&TEXT(_xlfn.XLOOKUP($I30,Assumptions!$B$30:$B$50,Assumptions!$C$30:$C$50,0),"0.0#")&" mechanism"))) | W30: inferred
A31: GEO_H_CHI | B31: Chicago | C31: Hub | D31: USA | E31: United States | F31: Chicago | S31: =IF($C31<>"Organisation","",IF(OR($P31<>"",$Q31<>""),IF($P31<>"",IF($Q31<>"",($P31+$Q31)/2,$P31),$Q31),ROUND(_xlfn.XLOOKUP($N31,Assumptions!$B$5:$B$9,Assumptions!$C$5:$C$9,0)*_xlfn.XLOOKUP($G31,Assumptions!$B$13:$B$26,Assumptions!$C$13:$C$26,0)*_xlfn.XLOOKUP($I31,Assumptions!$B$30:$B$50,Assumptions!$C$30:$C$50,0),0))) | T31: =IF($C31<>"Organisation","",IF(OR($P31<>"",$Q31<>""),"Documented in source - midpoint of annual_intake_low/high",IF($I31="","No confirmed programme - modelled as zero",$N31&" base x "&TEXT(_xlfn.XLOOKUP($G31,Assumptions!$B$13:$B$26,Assumptions!$C$13:$C$26,0),"0.0#")&" sector x "&TEXT(_xlfn.XLOOKUP($I31,Assumptions!$B$30:$B$50,Assumptions!$C$30:$C$50,0),"0.0#")&" mechanism"))) | W31: inferred
A32: GEO_H_BOS | B32: Boston | C32: Hub | D32: USA | E32: United States | F32: Boston | S32: =IF($C32<>"Organisation","",IF(OR($P32<>"",$Q32<>""),IF($P32<>"",IF($Q32<>"",($P32+$Q32)/2,$P32),$Q32),ROUND(_xlfn.XLOOKUP($N32,Assumptions!$B$5:$B$9,Assumptions!$C$5:$C$9,0)*_xlfn.XLOOKUP($G32,Assumptions!$B$13:$B$26,Assumptions!$C$13:$C$26,0)*_xlfn.XLOOKUP($I32,Assumptions!$B$30:$B$50,Assumptions!$C$30:$C$50,0),0))) | T32: =IF($C32<>"Organisation","",IF(OR($P32<>"",$Q32<>""),"Documented in source - midpoint of annual_intake_low/high",IF($I32="","No confirmed programme - modelled as zero",$N32&" base x "&TEXT(_xlfn.XLOOKUP($G32,Assumptions!$B$13:$B$26,Assumptions!$C$13:$C$26,0),"0.0#")&" sector x "&TEXT(_xlfn.XLOOKUP($I32,Assumptions!$B$30:$B$50,Assumptions!$C$30:$C$50,0),"0.0#")&" mechanism"))) | W32: inferred
A33: GEO_H_CLT | B33: Charlotte | C33: Hub | D33: USA | E33: United States | F33: Charlotte | S33: =IF($C33<>"Organisation","",IF(OR($P33<>"",$Q33<>""),IF($P33<>"",IF($Q33<>"",($P33+$Q33)/2,$P33),$Q33),ROUND(_xlfn.XLOOKUP($N33,Assumptions!$B$5:$B$9,Assumptions!$C$5:$C$9,0)*_xlfn.XLOOKUP($G33,Assumptions!$B$13:$B$26,Assumptions!$C$13:$C$26,0)*_xlfn.XLOOKUP($I33,Assumptions!$B$30:$B$50,Assumptions!$C$30:$C$50,0),0))) | T33: =IF($C33<>"Organisation","",IF(OR($P33<>"",$Q33<>""),"Documented in source - midpoint of annual_intake_low/high",IF($I33="","No confirmed programme - modelled as zero",$N33&" base x "&TEXT(_xlfn.XLOOKUP($G33,Assumptions!$B$13:$B$26,Assumptions!$C$13:$C$26,0),"0.0#")&" sector x "&TEXT(_xlfn.XLOOKUP($I33,Assumptions!$B$30:$B$50,Assumptions!$C$30:$C$50,0),"0.0#")&" mechanism"))) | W33: inferred
A34: GEO_H_SFO | B34: San Francisco Bay Area | C34: Hub | D34: USA | E34: United States | F34: San Francisco Bay Area | S34: =IF($C34<>"Organisation","",IF(OR($P34<>"",$Q34<>""),IF($P34<>"",IF($Q34<>"",($P34+$Q34)/2,$P34),$Q34),ROUND(_xlfn.XLOOKUP($N34,Assumptions!$B$5:$B$9,Assumptions!$C$5:$C$9,0)*_xlfn.XLOOKUP($G34,Assumptions!$B$13:$B$26,Assumptions!$C$13:$C$26,0)*_xlfn.XLOOKUP($I34,Assumptions!$B$30:$B$50,Assumptions!$C$30:$C$50,0),0))) | T34: =IF($C34<>"Organisation","",IF(OR($P34<>"",$Q34<>""),"Documented in source - midpoint of annual_intake_low/high",IF($I34="","No confirmed programme - modelled as zero",$N34&" base x "&TEXT(_xlfn.XLOOKUP($G34,Assumptions!$B$13:$B$26,Assumptions!$C$13:$C$26,0),"0.0#")&" sector x "&TEXT(_xlfn.XLOOKUP($I34,Assumptions!$B$30:$B$50,Assumptions!$C$30:$C$50,0),"0.0#")&" mechanism"))) | W34: inferred
A35: GEO_H_MIA | B35: Miami | C35: Hub | D35: USA | E35: United States | F35: Miami | S35: =IF($C35<>"Organisation","",IF(OR($P35<>"",$Q35<>""),IF($P35<>"",IF($Q35<>"",($P35+$Q35)/2,$P35),$Q35),ROUND(_xlfn.XLOOKUP($N35,Assumptions!$B$5:$B$9,Assumptions!$C$5:$C$9,0)*_xlfn.XLOOKUP($G35,Assumptions!$B$13:$B$26,Assumptions!$C$13:$C$26,0)*_xlfn.XLOOKUP($I35,Assumptions!$B$30:$B$50,Assumptions!$C$30:$C$50,0),0))) | T35: =IF($C35<>"Organisation","",IF(OR($P35<>"",$Q35<>""),"Documented in source - midpoint of annual_intake_low/high",IF($I35="","No confirmed programme - modelled as zero",$N35&" base x "&TEXT(_xlfn.XLOOKUP($G35,Assumptions!$B$13:$B$26,Assumptions!$C$13:$C$26,0),"0.0#")&" sector x "&TEXT(_xlfn.XLOOKUP($I35,Assumptions!$B$30:$B$50,Assumptions!$C$30:$C$50,0),"0.0#")&" mechanism"))) | W35: inferred
A36: GEO_H_LAX | B36: Los Angeles | C36: Hub | D36: USA | E36: United States | F36: Los Angeles | S36: =IF($C36<>"Organisation","",IF(OR($P36<>"",$Q36<>""),IF($P36<>"",IF($Q36<>"",($P36+$Q36)/2,$P36),$Q36),ROUND(_xlfn.XLOOKUP($N36,Assumptions!$B$5:$B$9,Assumptions!$C$5:$C$9,0)*_xlfn.XLOOKUP($G36,Assumptions!$B$13:$B$26,Assumptions!$C$13:$C$26,0)*_xlfn.XLOOKUP($I36,Assumptions!$B$30:$B$50,Assumptions!$C$30:$C$50,0),0))) | T36: =IF($C36<>"Organisation","",IF(OR($P36<>"",$Q36<>""),"Documented in source - midpoint of annual_intake_low/high",IF($I36="","No confirmed programme - modelled as zero",$N36&" base x "&TEXT(_xlfn.XLOOKUP($G36,Assumptions!$B$13:$B$26,Assumptions!$C$13:$C$26,0),"0.0#")&" sector x "&TEXT(_xlfn.XLOOKUP($I36,Assumptions!$B$30:$B$50,Assumptions!$C$30:$C$50,0),"0.0#")&" mechanism"))) | W36: inferred
A37: GEO_H_PHL | B37: Philadelphia area | C37: Hub | D37: USA | E37: United States | F37: Philadelphia area | S37: =IF($C37<>"Organisation","",IF(OR($P37<>"",$Q37<>""),IF($P37<>"",IF($Q37<>"",($P37+$Q37)/2,$P37),$Q37),ROUND(_xlfn.XLOOKUP($N37,Assumptions!$B$5:$B$9,Assumptions!$C$5:$C$9,0)*_xlfn.XLOOKUP($G37,Assumptions!$B$13:$B$26,Assumptions!$C$13:$C$26,0)*_xlfn.XLOOKUP($I37,Assumptions!$B$30:$B$50,Assumptions!$C$30:$C$50,0),0))) | T37: =IF($C37<>"Organisation","",IF(OR($P37<>"",$Q37<>""),"Documented in source - midpoint of annual_intake_low/high",IF($I37="","No confirmed programme - modelled as zero",$N37&" base x "&TEXT(_xlfn.XLOOKUP($G37,Assumptions!$B$13:$B$26,Assumptions!$C$13:$C$26,0),"0.0#")&" sector x "&TEXT(_xlfn.XLOOKUP($I37,Assumptions!$B$30:$B$50,Assumptions!$C$30:$C$50,0),"0.0#")&" mechanism"))) | W37: inferred
A38: GEO_H_USOTH | B38: Other US metro | C38: Hub | D38: USA | E38: United States | F38: Other US metro | S38: =IF($C38<>"Organisation","",IF(OR($P38<>"",$Q38<>""),IF($P38<>"",IF($Q38<>"",($P38+$Q38)/2,$P38),$Q38),ROUND(_xlfn.XLOOKUP($N38,Assumptions!$B$5:$B$9,Assumptions!$C$5:$C$9,0)*_xlfn.XLOOKUP($G38,Assumptions!$B$13:$B$26,Assumptions!$C$13:$C$26,0)*_xlfn.XLOOKUP($I38,Assumptions!$B$30:$B$50,Assumptions!$C$30:$C$50,0),0))) | T38: =IF($C38<>"Organisation","",IF(OR($P38<>"",$Q38<>""),"Documented in source - midpoint of annual_intake_low/high",IF($I38="","No confirmed programme - modelled as zero",$N38&" base x "&TEXT(_xlfn.XLOOKUP($G38,Assumptions!$B$13:$B$26,Assumptions!$C$13:$C$26,0),"0.0#")&" sector x "&TEXT(_xlfn.XLOOKUP($I38,Assumptions!$B$30:$B$50,Assumptions!$C$30:$C$50,0),"0.0#")&" mechanism"))) | W38: inferred
A39: GEO_H_MUM | B39: Mumbai | C39: Hub | D39: India | E39: India | F39: Mumbai | S39: =IF($C39<>"Organisation","",IF(OR($P39<>"",$Q39<>""),IF($P39<>"",IF($Q39<>"",($P39+$Q39)/2,$P39),$Q39),ROUND(_xlfn.XLOOKUP($N39,Assumptions!$B$5:$B$9,Assumptions!$C$5:$C$9,0)*_xlfn.XLOOKUP($G39,Assumptions!$B$13:$B$26,Assumptions!$C$13:$C$26,0)*_xlfn.XLOOKUP($I39,Assumptions!$B$30:$B$50,Assumptions!$C$30:$C$50,0),0))) | T39: =IF($C39<>"Organisation","",IF(OR($P39<>"",$Q39<>""),"Documented in source - midpoint of annual_intake_low/high",IF($I39="","No confirmed programme - modelled as zero",$N39&" base x "&TEXT(_xlfn.XLOOKUP($G39,Assumptions!$B$13:$B$26,Assumptions!$C$13:$C$26,0),"0.0#")&" sector x "&TEXT(_xlfn.XLOOKUP($I39,Assumptions!$B$30:$B$50,Assumptions!$C$30:$C$50,0),"0.0#")&" mechanism"))) | W39: source
A40: GEO_H_BLR | B40: Bengaluru | C40: Hub | D40: India | E40: India | F40: Bengaluru | S40: =IF($C40<>"Organisation","",IF(OR($P40<>"",$Q40<>""),IF($P40<>"",IF($Q40<>"",($P40+$Q40)/2,$P40),$Q40),ROUND(_xlfn.XLOOKUP($N40,Assumptions!$B$5:$B$9,Assumptions!$C$5:$C$9,0)*_xlfn.XLOOKUP($G40,Assumptions!$B$13:$B$26,Assumptions!$C$13:$C$26,0)*_xlfn.XLOOKUP($I40,Assumptions!$B$30:$B$50,Assumptions!$C$30:$C$50,0),0))) | T40: =IF($C40<>"Organisation","",IF(OR($P40<>"",$Q40<>""),"Documented in source - midpoint of annual_intake_low/high",IF($I40="","No confirmed programme - modelled as zero",$N40&" base x "&TEXT(_xlfn.XLOOKUP($G40,Assumptions!$B$13:$B$26,Assumptions!$C$13:$C$26,0),"0.0#")&" sector x "&TEXT(_xlfn.XLOOKUP($I40,Assumptions!$B$30:$B$50,Assumptions!$C$30:$C$50,0),"0.0#")&" mechanism"))) | W40: source
A41: GEO_H_HYD | B41: Hyderabad | C41: Hub | D41: India | E41: India | F41: Hyderabad | S41: =IF($C41<>"Organisation","",IF(OR($P41<>"",$Q41<>""),IF($P41<>"",IF($Q41<>"",($P41+$Q41)/2,$P41),$Q41),ROUND(_xlfn.XLOOKUP($N41,Assumptions!$B$5:$B$9,Assumptions!$C$5:$C$9,0)*_xlfn.XLOOKUP($G41,Assumptions!$B$13:$B$26,Assumptions!$C$13:$C$26,0)*_xlfn.XLOOKUP($I41,Assumptions!$B$30:$B$50,Assumptions!$C$30:$C$50,0),0))) | T41: =IF($C41<>"Organisation","",IF(OR($P41<>"",$Q41<>""),"Documented in source - midpoint of annual_intake_low/high",IF($I41="","No confirmed programme - modelled as zero",$N41&" base x "&TEXT(_xlfn.XLOOKUP($G41,Assumptions!$B$13:$B$26,Assumptions!$C$13:$C$26,0),"0.0#")&" sector x "&TEXT(_xlfn.XLOOKUP($I41,Assumptions!$B$30:$B$50,Assumptions!$C$30:$C$50,0),"0.0#")&" mechanism"))) | W41: source
... A70: GEO_H_LON | B70: London | C70: Hub | D70: United Kingdom | E70: United Kingdom | F70: London | S70: =IF($C70<>"Organisation","",IF(OR($P70<>"",$Q70<>""),IF($P70<>"",IF($Q70<>"",($P70+$Q70)/2,$P70),$Q70),ROUND(_xlfn.XLOOKUP($N70,Assumptions!$B$5:$B$9,Assumptions!$C$5:$C$9,0)*_xlfn.XLOOKUP($G70,Assumptions!$B$13:$B$26,Assumptions!$C$13:$C$26,0)*_xlfn.XLOOKUP($I70,Assumptions!$B$30:$B$50,Assumptions!$C$30:$C$50,0),0))) | T70: =IF($C70<>"Organisation","",IF(OR($P70<>"",$Q70<>""),"Documented in source - midpoint of annual_intake_low/high",IF($I70="","No confirmed programme - modelled as zero",$N70&" base x "&TEXT(_xlfn.XLOOKUP($G70,Assumptions!$B$13:$B$26,Assumptions!$C$13:$C$26,0),"0.0#")&" sector x "&TEXT(_xlfn.XLOOKUP($I70,Assumptions!$B$30:$B$50,Assumptions!$C$30:$C$50,0),"0.0#")&" mechanism"))) | W70: inferred
A71: SEC_IB_BB | B71: Investment Banking - Bulge Bracket | C71: Sector | S71: =IF($C71<>"Organisation","",IF(OR($P71<>"",$Q71<>""),IF($P71<>"",IF($Q71<>"",($P71+$Q71)/2,$P71),$Q71),ROUND(_xlfn.XLOOKUP($N71,Assumptions!$B$5:$B$9,Assumptions!$C$5:$C$9,0)*_xlfn.XLOOKUP($G71,Assumptions!$B$13:$B$26,Assumptions!$C$13:$C$26,0)*_xlfn.XLOOKUP($I71,Assumptions!$B$30:$B$50,Assumptions!$C$30:$C$50,0),0))) | T71: =IF($C71<>"Organisation","",IF(OR($P71<>"",$Q71<>""),"Documented in source - midpoint of annual_intake_low/high",IF($I71="","No confirmed programme - modelled as zero",$N71&" base x "&TEXT(_xlfn.XLOOKUP($G71,Assumptions!$B$13:$B$26,Assumptions!$C$13:$C$26,0),"0.0#")&" sector x "&TEXT(_xlfn.XLOOKUP($I71,Assumptions!$B$30:$B$50,Assumptions!$C$30:$C$50,0),"0.0#")&" mechanism")))
A72: SEC_IB_EB | B72: Investment Banking - Elite Boutique / Independent Advisory | C72: Sector | S72: =IF($C72<>"Organisation","",IF(OR($P72<>"",$Q72<>""),IF($P72<>"",IF($Q72<>"",($P72+$Q72)/2,$P72),$Q72),ROUND(_xlfn.XLOOKUP($N72,Assumptions!$B$5:$B$9,Assumptions!$C$5:$C$9,0)*_xlfn.XLOOKUP($G72,Assumptions!$B$13:$B$26,Assumptions!$C$13:$C$26,0)*_xlfn.XLOOKUP($I72,Assumptions!$B$30:$B$50,Assumptions!$C$30:$C$50,0),0))) | T72: =IF($C72<>"Organisation","",IF(OR($P72<>"",$Q72<>""),"Documented in source - midpoint of annual_intake_low/high",IF($I72="","No confirmed programme - modelled as zero",$N72&" base x "&TEXT(_xlfn.XLOOKUP($G72,Assumptions!$B$13:$B$26,Assumptions!$C$13:$C$26,0),"0.0#")&" sector x "&TEXT(_xlfn.XLOOKUP($I72,Assumptions!$B$30:$B$50,Assumptions!$C$30:$C$50,0),"0.0#")&" mechanism")))
A73: SEC_QUANT | B73: Proprietary Trading / Quant | C73: Sector | S73: =IF($C73<>"Organisation","",IF(OR($P73<>"",$Q73<>""),IF($P73<>"",IF($Q73<>"",($P73+$Q73)/2,$P73),$Q73),ROUND(_xlfn.XLOOKUP($N73,Assumptions!$B$5:$B$9,Assumptions!$C$5:$C$9,0)*_xlfn.XLOOKUP($G73,Assumptions!$B$13:$B$26,Assumptions!$C$13:$C$26,0)*_xlfn.XLOOKUP($I73,Assumptions!$B$30:$B$50,Assumptions!$C$30:$C$50,0),0))) | T73: =IF($C73<>"Organisation","",IF(OR($P73<>"",$Q73<>""),"Documented in source - midpoint of annual_intake_low/high",IF($I73="","No confirmed programme - modelled as zero",$N73&" base x "&TEXT(_xlfn.XLOOKUP($G73,Assumptions!$B$13:$B$26,Assumptions!$C$13:$C$26,0),"0.0#")&" sector x "&TEXT(_xlfn.XLOOKUP($I73,Assumptions!$B$30:$B$50,Assumptions!$C$30:$C$50,0),"0.0#")&" mechanism")))
A74: SEC_COMM | B74: Commercial / Retail Banking | C74: Sector | S74: =IF($C74<>"Organisation","",IF(OR($P74<>"",$Q74<>""),IF($P74<>"",IF($Q74<>"",($P74+$Q74)/2,$P74),$Q74),ROUND(_xlfn.XLOOKUP($N74,Assumptions!$B$5:$B$9,Assumptions!$C$5:$C$9,0)*_xlfn.XLOOKUP($G74,Assumptions!$B$13:$B$26,Assumptions!$C$13:$C$26,0)*_xlfn.XLOOKUP($I74,Assumptions!$B$30:$B$50,Assumptions!$C$30:$C$50,0),0))) | T74: =IF($C74<>"Organisation","",IF(OR($P74<>"",$Q74<>""),"Documented in source - midpoint of annual_intake_low/high",IF($I74="","No confirmed programme - modelled as zero",$N74&" base x "&TEXT(_xlfn.XLOOKUP($G74,Assumptions!$B$13:$B$26,Assumptions!$C$13:$C$26,0),"0.0#")&" sector x "&TEXT(_xlfn.XLOOKUP($I74,Assumptions!$B$30:$B$50,Assumptions!$C$30:$C$50,0),"0.0#")&" mechanism")))
A75: SEC_CUST | B75: Custodian / Asset Servicing / Fund Administration | C75: Sector | S75: =IF($C75<>"Organisation","",IF(OR($P75<>"",$Q75<>""),IF($P75<>"",IF($Q75<>"",($P75+$Q75)/2,$P75),$Q75),ROUND(_xlfn.XLOOKUP($N75,Assumptions!$B$5:$B$9,Assumptions!$C$5:$C$9,0)*_xlfn.XLOOKUP($G75,Assumptions!$B$13:$B$26,Assumptions!$C$13:$C$26,0)*_xlfn.XLOOKUP($I75,Assumptions!$B$30:$B$50,Assumptions!$C$30:$C$50,0),0))) | T75: =IF($C75<>"Organisation","",IF(OR($P75<>"",$Q75<>""),"Documented in source - midpoint of annual_intake_low/high",IF($I75="","No confirmed programme - modelled as zero",$N75&" base x "&TEXT(_xlfn.XLOOKUP($G75,Assumptions!$B$13:$B$26,Assumptions!$C$13:$C$26,0),"0.0#")&" sector x "&TEXT(_xlfn.XLOOKUP($I75,Assumptions!$B$30:$B$50,Assumptions!$C$30:$C$50,0),"0.0#")&" mechanism")))
A76: SEC_AM | B76: Investment / Asset Management | C76: Sector | S76: =IF($C76<>"Organisation","",IF(OR($P76<>"",$Q76<>""),IF($P76<>"",IF($Q76<>"",($P76+$Q76)/2,$P76),$Q76),ROUND(_xlfn.XLOOKUP($N76,Assumptions!$B$5:$B$9,Assumptions!$C$5:$C$9,0)*_xlfn.XLOOKUP($G76,Assumptions!$B$13:$B$26,Assumptions!$C$13:$C$26,0)*_xlfn.XLOOKUP($I76,Assumptions!$B$30:$B$50,Assumptions!$C$30:$C$50,0),0))) | T76: =IF($C76<>"Organisation","",IF(OR($P76<>"",$Q76<>""),"Documented in source - midpoint of annual_intake_low/high",IF($I76="","No confirmed programme - modelled as zero",$N76&" base x "&TEXT(_xlfn.XLOOKUP($G76,Assumptions!$B$13:$B$26,Assumptions!$C$13:$C$26,0),"0.0#")&" sector x "&TEXT(_xlfn.XLOOKUP($I76,Assumptions!$B$30:$B$50,Assumptions!$C$30:$C$50,0),"0.0#")&" mechanism")))
...

Sheet Edges
A1: edge_id | B1: source_id | C1: target_id | D1: edge_type | E1: directed | F1: weight | G1: notes
A2: E0001 | B2: GEO_C_US | C2: GEO_R_USA | D2: PART_OF | E2: TRUE
A3: E0002 | B3: GEO_C_IN | C3: GEO_R_INDIA | D3: PART_OF | E3: TRUE
A4: E0003 | B4: GEO_C_CN | C4: GEO_R_CHINA | D4: PART_OF | E4: TRUE
A5: E0004 | B5: GEO_C_BR | C5: GEO_R_LATAM | D5: PART_OF | E5: TRUE
A6: E0005 | B6: GEO_C_MX | C6: GEO_R_LATAM | D6: PART_OF | E6: TRUE
A7: E0006 | B7: GEO_C_CO | C7: GEO_R_LATAM | D7: PART_OF | E7: TRUE
A8: E0007 | B8: GEO_C_CL | C8: GEO_R_LATAM | D8: PART_OF | E8: TRUE
A9: E0008 | B9: GEO_C_PE | C9: GEO_R_LATAM | D9: PART_OF | E9: TRUE
A10: E0009 | B10: GEO_C_AR | C10: GEO_R_LATAM | D10: PART_OF | E10: TRUE
A11: E0010 | B11: GEO_C_DE | C11: GEO_R_EUROPE | D11: PART_OF | E11: TRUE
A12: E0011 | B12: GEO_C_FR | C12: GEO_R_EUROPE | D12: PART_OF | E12: TRUE
A13: E0012 | B13: GEO_C_CH | C13: GEO_R_EUROPE | D13: PART_OF | E13: TRUE
... A318: E0455 | B318: ORG_LUFAX | C318: SEC_FINTECH | D318: IN_SECTOR | E318: TRUE
A319: E0457 | B319: ORG_JPM | C319: GEO_H_BLR | D319: LOCATED_IN | E319: TRUE | G319: India GCC site (Channel c)
A320: E0458 | B320: ORG_JPM | C320: GEO_H_HYD | D320: LOCATED_IN | E320: TRUE | G320: India GCC site (Channel c)
A321: E0459 | B321: ORG_JPM | C321: GEO_H_MUM | D321: LOCATED_IN | E321: TRUE | G321: India GCC site (Channel c)
A322: E0460 | B322: ORG_GS | C322: GEO_H_BLR | D322: LOCATED_IN | E322: TRUE | G322: India GCC site (Channel c)
A323: E0461 | B323: ORG_GS | C323: GEO_H_HYD | D323: LOCATED_IN | E323: TRUE | G323: India GCC site (Channel c)
A324: E0462 | B324: ORG_MS | C324: GEO_H_MUM | D324: LOCATED_IN | E324: TRUE | G324: India GCC site (Channel c)
A325: E0463 | B325: ORG_CITI | C325: GEO_H_MUM | D325: LOCATED_IN | E325: TRUE | G325: India GCC site (Channel c)
A326: E0464 | B326: ORG_HSBC | C326: GEO_H_INOTH | D326: LOCATED_IN | E326: TRUE | G326: India GCC site (Channel c)
A327: E0465 | B327: ORG_BARC | C327: GEO_H_INOTH | D327: LOCATED_IN | E327: TRUE | G327: India GCC site (Channel c)
A328: E0466 | B328: ORG_STAN | C328: GEO_H_INOTH | D328: LOCATED_IN | E328: TRUE | G328: India GCC site (Channel c)
A329: E0467 | B329: ORG_STT | C329: GEO_H_INOTH | D329: LOCATED_IN | E329: TRUE | G329: India GCC site (Channel c)
A330: E0468 | B330: ORG_NTRS | C330: GEO_H_INOTH | D330: LOCATED_IN | E330: TRUE | G330: India GCC site (Channel c)
... A342: E0544 | B342: ORG_TENCENTFIT | C342: ORG_CCB | D342: COMPETES_FOR_TALENT | E342: FALSE | G342: Fintech giants compete head-to-head with Big Four state banks for the same talent
A343: E0545 | B343: ORG_ITAU | C343: GEO_H_SAO | D343: LOCATED_IN | E343: TRUE
A344: E0546 | B344: ORG_ITAU | C344: SEC_COMM | D344: IN_SECTOR | E344: TRUE
A345: E0548 | B345: ORG_BRADESCO | C345: GEO_H_SAO | D345: LOCATED_IN | E345: TRUE
A346: E0549 | B346: ORG_BRADESCO | C346: SEC_COMM | D346: IN_SECTOR | E346: TRUE
A347: E0551 | B347: ORG_BB | C347: GEO_H_SAO | D347: LOCATED_IN | E347: TRUE
A348: E0552 | B348: ORG_BB | C348: SEC_COMM | D348: IN_SECTOR | E348: TRUE
A349: E0554 | B349: ORG_SANBR | C349: GEO_H_SAO | D349: LOCATED_IN | E349: TRUE
A350: E0555 | B350: ORG_SANBR | C350: SEC_COMM | D350: IN_SECTOR | E350: TRUE
A351: E0557 | B351: ORG_BTG | C351: GEO_H_SAO | D351: LOCATED_IN | E351: TRUE
A352: E0558 | B352: ORG_BTG | C352: SEC_IB_EB | D352: IN_SECTOR | E352: TRUE
A353: E0560 | B353: ORG_ENFORCE | C353: GEO_H_SAO | D353: LOCATED_IN | E353: TRUE
A354: E0561 | B354: ORG_ENFORCE | C354: SEC_NBFC | D354: IN_SECTOR | E354: TRUE
... A480: E0748 | B480: ORG_EIB | C480: SEC_POLICY | D480: IN_SECTOR | E480: TRUE
...

Sheet Vocabulary
A1: Field / vocabulary | B1: Allowed value | C1: Meaning
A2: node_type | B2: Region | C2: One of the five source regions (plus 'Other' for out-of-scope home markets)
A3: node_type | B3: Country | C3: National market; PART_OF a Region
A4: node_type | B4: Hub | C4: City / metro financial hub; PART_OF a Country
A5: node_type | B5: Organisation | C5: Employer node - the knowledge-inflow node in the simulator
A6: node_type | B6: Sector | C6: Sector taxonomy node
A7: node_type | B7: Mechanism | C7: Entry mechanism (carries cycle_timing and lead_time_months)
A8: node_type | B8: TalentPool | C8: Campus system or recruitment intermediary supplying graduates
A9: edge_type | B9: PART_OF | C9: Geographic hierarchy: Hub -> Country -> Region
A10: edge_type | B10: LOCATED_IN | C10: Organisation has a graduate-recruiting site in this hub (multiple per org = multinational)
A11: edge_type | B11: IN_SECTOR | C11: Organisation belongs to this sector
A12: edge_type | B12: RECRUITS_VIA | C12: Organisation uses this entry mechanism (inherit lead_time_months from the mechanism node)
... A41: intake_estimate_central | B41: Whole number, or blank for non-organisation rows | C41: Zero means no programme, NOT unknown

Sheet Summary
A1: Graph dataset summary
A2: All figures below are formulas over the Nodes and Edges sheets.
A4: NODES BY TYPE | B4: Count
A5: Region | B5: =COUNTIF(tblNodes[node_type],$A5) -> 9
A6: Country | B6: =COUNTIF(tblNodes[node_type],$A6) -> 27
A7: Hub | B7: =COUNTIF(tblNodes[node_type],$A7) -> 57
A8: Organisation | B8: =COUNTIF(tblNodes[node_type],$A8) -> 298
A9: Sector | B9: =COUNTIF(tblNodes[node_type],$A9) -> 14
A10: Mechanism (removed at user request) | B10: =COUNTIF(tblNodes[node_type],$A10) -> 0
A11: TalentPool (removed at user request) | B11: =COUNTIF(tblNodes[node_type],$A11) -> 0
A12: Total nodes | B12: =COUNTA(tblNodes[node_id]) -> 405
A14: ORGANISATIONS BY REGION | B14: Count | C14: Distinct hubs | D14: Est. annual intake
A15: USA | B15: =COUNTIFS(tblNodes[node_type],"Organisation",tblNodes[region],$A15) -> 67 | C15: =COUNTIFS(tblNodes[node_type],"Hub",tblNodes[region],$A15) -> 9 | D15: =SUMIFS(tblNodes[intake_estimate_central],tblNodes[node_type],"Organisation",tblNodes[region],$A15) -> 10579
A16: India | B16: =COUNTIFS(tblNodes[node_type],"Organisation",tblNodes[region],$A16) -> 23 | C16: =COUNTIFS(tblNodes[node_type],"Hub",tblNodes[region],$A16) -> 4 | D16: =SUMIFS(tblNodes[intake_estimate_central],tblNodes[node_type],"Organisation",tblNodes[region],$A16) -> 5837
A17: China | B17: =COUNTIFS(tblNodes[node_type],"Organisation",tblNodes[region],$A17) -> 34 | C17: =COUNTIFS(tblNodes[node_type],"Hub",tblNodes[region],$A17) -> 5 | D17: =SUMIFS(tblNodes[intake_estimate_central],tblNodes[node_type],"Organisation",tblNodes[region],$A17) -> 17460
A18: Latin America | B18: =COUNTIFS(tblNodes[node_type],"Organisation",tblNodes[region],$A18) -> 25 | C18: =COUNTIFS(tblNodes[node_type],"Hub",tblNodes[region],$A18) -> 7 | D18: =SUMIFS(tblNodes[intake_estimate_central],tblNodes[node_type],"Organisation",tblNodes[region],$A18) -> 3183
A19: Continental Europe | B19: =COUNTIFS(tblNodes[node_type],"Organisation",tblNodes[region],$A19) -> 44 | C19: =COUNTIFS(tblNodes[node_type],"Hub",tblNodes[region],$A19) -> 15 | D19: =SUMIFS(tblNodes[intake_estimate_central],tblNodes[node_type],"Organisation",tblNodes[region],$A19) -> 8187
A20: United Kingdom | B20: =COUNTIFS(tblNodes[node_type],"Organisation",tblNodes[region],$A20) -> 52 | C20: =COUNTIFS(tblNodes[node_type],"Hub",tblNodes[region],$A20) -> 9 | D20: =SUMIFS(tblNodes[intake_estimate_central],tblNodes[node_type],"Organisation",tblNodes[region],$A20) -> 7268
A21: Asia-Pacific (ex-China) | B21: =COUNTIFS(tblNodes[node_type],"Organisation",tblNodes[region],$A21) -> 31 | C21: =COUNTIFS(tblNodes[node_type],"Hub",tblNodes[region],$A21) -> 4 | D21: =SUMIFS(tblNodes[intake_estimate_central],tblNodes[node_type],"Organisation",tblNodes[region],$A21) -> 8612
A22: Middle East | B22: =COUNTIFS(tblNodes[node_type],"Organisation",tblNodes[region],$A22) -> 10 | C22: =COUNTIFS(tblNodes[node_type],"Hub",tblNodes[region],$A22) -> 2 | D22: =SUMIFS(tblNodes[intake_estimate_central],tblNodes[node_type],"Organisation",tblNodes[region],$A22) -> 841
A23: Canada | B23: =COUNTIFS(tblNodes[node_type],"Organisation",tblNodes[region],$A23) -> 12 | C23: =COUNTIFS(tblNodes[node_type],"Hub",tblNodes[region],$A23) -> 2 | D23: =SUMIFS(tblNodes[intake_estimate_central],tblNodes[node_type],"Organisation",tblNodes[region],$A23) -> 2739
A24: Total | B24: =SUM(B15:B23) -> 298 | D24: =SUM(D15:D23) -> 64706
A25: ORGANISATIONS BY SECTOR | B25: Count
A26: Investment Banking - Bulge Bracket | B26: =COUNTIFS(tblNodes[node_type],"Organisation",tblNodes[sector],$A26) -> 12
A27: Investment Banking - Elite Boutique / Independent Advisory | B27: =COUNTIFS(tblNodes[node_type],"Organisation",tblNodes[sector],$A27) -> 22
A28: Proprietary Trading / Quant | B28: =COUNTIFS(tblNodes[node_type],"Organisation",tblNodes[sector],$A28) -> 12
A29: Commercial / Retail Banking | B29: =COUNTIFS(tblNodes[node_type],"Organisation",tblNodes[sector],$A29) -> 106
A30: Custodian / Asset Servicing / Fund Administration | B30: =COUNTIFS(tblNodes[node_type],"Organisation",tblNodes[sector],$A30) -> 3
A31: Investment / Asset Management | B31: =COUNTIFS(tblNodes[node_type],"Organisation",tblNodes[sector],$A31) -> 37
A32: Insurance | B32: =COUNTIFS(tblNodes[node_type],"Organisation",tblNodes[sector],$A32) -> 42
A33: Ratings Agencies & Financial Data | B33: =COUNTIFS(tblNodes[node_type],"Organisation",tblNodes[sector],$A33) -> 14
A34: Consulting / Professional Services | B34: =COUNTIFS(tblNodes[node_type],"Organisation",tblNodes[sector],$A34) -> 9
A35: Fintech / Tech-Finance | B35: =COUNTIFS(tblNodes[node_type],"Organisation",tblNodes[sector],$A35) -> 8
A36: Policy / Development Bank | B36: =COUNTIFS(tblNodes[node_type],"Organisation",tblNodes[sector],$A36) -> 6
A37: Central Bank / Supervisor | B37: =COUNTIFS(tblNodes[node_type],"Organisation",tblNodes[sector],$A37) -> 13
... A39: NBFC / Diversified Financial | B39: =COUNTIFS(tblNodes[node_type],"Organisation",tblNodes[sector],$A39) -> 3
A41: EDGES BY TYPE | B41: Count
A42: PART_OF | B42: =COUNTIF(tblEdges[edge_type],$A42) -> 84
A43: LOCATED_IN | B43: =COUNTIF(tblEdges[edge_type],$A43) -> 472
A44: IN_SECTOR | B44: =COUNTIF(tblEdges[edge_type],$A44) -> 298
...

Sheet Assumptions
A1: Intake estimation assumptions
B2: The intake_estimate_central column on Nodes is a FORMULA, not typed numbers. Where the source document gives a cohort size, the documented figure wins. Otherwise the estimate is: size-band base x sector factor x mechanism factor. Retune any cell below and every estimate updates.
B3: These are order-of-magnitude judgements, not sourced figures. Treat them as a starting point for weighting the graph, not as data.
B4: 1. Size-band base (graduates per year) | C4: Base
B5: Mega | C5: 400
B6: Large | C6: 120
B7: Mid | C7: 30
B8: Boutique | C8: 8
B9: TBC | C9: 30
B12: 2. Sector factor | C12: Factor
B13: Investment Banking - Bulge Bracket | C13: 2
B14: Investment Banking - Elite Boutique / Independent Advisory | C14: 0.8
B15: Proprietary Trading / Quant | C15: 2
B16: Commercial / Retail Banking | C16: 1
B17: Custodian / Asset Servicing / Fund Administration | C17: 1.5
B18: Investment / Asset Management | C18: 0.8
B19: Insurance | C19: 1
B20: Ratings Agencies & Financial Data | C20: 1.5
B21: Consulting / Professional Services | C21: 3
B22: Fintech / Tech-Finance | C22: 1
B23: Policy / Development Bank | C23: 0.4
B24: Central Bank / Supervisor | C24: 1
... B26: NBFC / Diversified Financial | C26: 0.8
B29: 3. Mechanism factor | C29: Factor | D29: Rationale
B30: MECH_US_CONV | C30: 1 | D30: Internship-to-full-time conversion; cohort sized to the bank
B31: MECH_ACTUARIAL | C31: 0.5 | D31: Narrow technical track
B32: MECH_IN_EXAM | C32: 1.4 | D32: Centralised mass exam - hundreds of seats per bank per year
B33: MECH_IN_PGDBF | C33: 1.2 | D33: Hire-and-train diplomas run large cohorts
B34: MECH_IN_GCC | C34: 1 | D34: Elite-campus analyst intake
B35: MECH_CN_CYCLE | C35: 3 | D35: Quota-influenced autumn cycle; the source notes thousands hired per cycle
B36: MECH_BR_TRAINEE | C36: 0.25 | D36: A single annual trainee cohort is small and highly selective
B37: MECH_LATAM_ESTAGIO | C37: 0.8 | D37: Multiple internship cycles per year
B38: MECH_LATAM_CONCURSO | C38: 0.6 | D38: Public exam, irregular and not graduate-specific
B39: MECH_EU_ROTATIONAL | C39: 0.8 | D39: National-hub rotational schemes are mid-sized
B40: MECH_UK_SPRING | C40: 1 | D40: Spring Week funnel feeding a September analyst class
B41: MECH_UK_SCHEME | C41: 1 | D41: Direct autumn-to-September entry
... B47: MECH_CA_ROTATIONAL | C47: 1 | D47: Canadian new-grad rotational program, summer-internship fed

Sheet JSON
A1: {
A2: "nodes": [
A3: {"node_id":"GEO_R_USA","label":"USA","node_type":"Region","region":"USA","country":null,"hub_city":null,"sector":null,"subsector_tier":null,"entry_mechanism_id":null,"program_name":null,"program_length_months":null,"org_size_band":null,"size_basis":null,"annual_intake_low":null,"annual_intake_high":null,"applications_per_cycle":null,"intake_estimate_central":null,"intake_estimate_basis":null,"confirmation_status":null,"data_confidence":null,"geo_source":null,"notes":"Source region"},
A4: {"node_id":"GEO_R_INDIA","label":"India","node_type":"Region","region":"India","country":null,"hub_city":null,"sector":null,"subsector_tier":null,"entry_mechanism_id":null,"program_name":null,"program_length_months":null,"org_size_band":null,"size_basis":null,"annual_intake_low":null,"annual_intake_high":null,"applications_per_cycle":null,"intake_estimate_central":null,"intake_estimate_basis":null,"confirmation_status":null,"data_confidence":null,"geo_source":null,"notes":"Source region"},
A5: {"node_id":"GEO_R_CHINA","label":"China","node_type":"Region","region":"China","country":null,"hub_city":null,"sector":null,"subsector_tier":null,"entry_mechanism_id":null,"program_name":null,"program_length_months":null,"org_size_band":null,"size_basis":null,"annual_intake_low":null,"annual_intake_high":null,"applications_per_cycle":null,"intake_estimate_central":null,"intake_estimate_basis":null,"confirmation_status":null,"data_confidence":null,"geo_source":null,"notes":"Source region"},
A6: {"node_id":"GEO_R_LATAM","label":"Latin America","node_type":"Region","region":"Latin America","country":null,"hub_city":null,"sector":null,"subsector_tier":null,"entry_mechanism_id":null,"program_name":null,"program_length_months":null,"org_size_band":null,"size_basis":null,"annual_intake_low":null,"annual_intake_high":null,"applications_per_cycle":null,"intake_estimate_central":null,"intake_estimate_basis":null,"confirmation_status":null,"data_confidence":null,"geo_source":null,"notes":"Source region"},
A7: {"node_id":"GEO_R_EUROPE","label":"Continental Europe","node_type":"Region","region":"Continental Europe","country":null,"hub_city":null,"sector":null,"subsector_tier":null,"entry_mechanism_id":null,"program_name":null,"program_length_months":null,"org_size_band":null,"size_basis":null,"annual_intake_low":null,"annual_intake_high":null,"applications_per_cycle":null,"intake_estimate_central":null,"intake_estimate_basis":null,"confirmation_status":null,"data_confidence":null,"geo_source":null,"notes":"Source region"},
A8: {"node_id":"GEO_R_UK","label":"United Kingdom","node_type":"Region","region":"United Kingdom","country":null,"hub_city":null,"sector":null,"subsector_tier":null,"entry_mechanism_id":null,"program_name":null,"program_length_months":null,"org_size_band":null,"size_basis":null,"annual_intake_low":null,"annual_intake_high":null,"applications_per_cycle":null,"intake_estimate_central":null,"intake_estimate_basis":null,"confirmation_status":null,"data_confidence":null,"geo_source":null,"notes":"Source region 6 - added by research, not present in the source document (the source covers five regions and treats the UK list as its structural template only)"},
A9: {"node_id":"GEO_C_US","label":"United States","node_type":"Country","region":"USA","country":"United States","hub_city":null,"sector":null,"subsector_tier":null,"entry_mechanism_id":null,"program_name":null,"program_length_months":null,"org_size_band":null,"size_basis":null,"annual_intake_low":null,"annual_intake_high":null,"applications_per_cycle":null,"intake_estimate_central":null,"intake_estimate_basis":null,"confirmation_status":null,"data_confidence":null,"geo_source":null,"notes":null},
A10: {"node_id":"GEO_C_IN","label":"India","node_type":"Country","region":"India","country":"India","hub_city":null,"sector":null,"subsector_tier":null,"entry_mechanism_id":null,"program_name":null,"program_length_months":null,"org_size_band":null,"size_basis":null,"annual_intake_low":null,"annual_intake_high":null,"applications_per_cycle":null,"intake_estimate_central":null,"intake_estimate_basis":null,"confirmation_status":null,"data_confidence":null,"geo_source":null,"notes":null},
A11: {"node_id":"GEO_C_CN","label":"China","node_type":"Country","region":"China","country":"China","hub_city":null,"sector":null,"subsector_tier":null,"entry_mechanism_id":null,"program_name":null,"program_length_months":null,"org_size_band":null,"size_basis":null,"annual_intake_low":null,"annual_intake_high":null,"applications_per_cycle":null,"intake_estimate_central":null,"intake_estimate_basis":null,"confirmation_status":null,"data_confidence":null,"geo_source":null,"notes":null},
A12: {"node_id":"GEO_C_BR","label":"Brazil","node_type":"Country","region":"Latin America","country":"Brazil","hub_city":null,"sector":null,"subsector_tier":null,"entry_mechanism_id":null,"program_name":null,"program_length_months":null,"org_size_band":null,"size_basis":null,"annual_intake_low":null,"annual_intake_high":null,"applications_per_cycle":null,"intake_estimate_central":null,"intake_estimate_basis":null,"confirmation_status":null,"data_confidence":null,"geo_source":null,"notes":null},
... A1291: }
